2021-03-10 16:04:34,204 -  nornir.core -     INFO -        run() - Running task 'load_variable' with args {} on 6 hosts
2021-03-10 16:04:34,211 - nornir.core.task -    ERROR -      start() - Host 'R3': task 'Getting iBGP Config' failed with traceback:
Traceback (most recent call last):
  File "/usr/local/lib/python3.9/site-packages/nornir/core/task.py", line 98, in start
    r = self.task(self, **self.params)
TypeError: template_file() missing 1 required positional argument: 'path'

2021-03-10 16:04:34,212 - nornir.core.task -    ERROR -      start() - Host 'R1': task 'Getting iBGP Config' failed with traceback:
Traceback (most recent call last):
  File "/usr/local/lib/python3.9/site-packages/nornir/core/task.py", line 98, in start
    r = self.task(self, **self.params)
TypeError: template_file() missing 1 required positional argument: 'path'

2021-03-10 16:04:34,212 - nornir.core.task -    ERROR -      start() - Host 'RR-1': task 'Getting iBGP Config' failed with traceback:
Traceback (most recent call last):
  File "/usr/local/lib/python3.9/site-packages/nornir/core/task.py", line 98, in start
    r = self.task(self, **self.params)
TypeError: template_file() missing 1 required positional argument: 'path'

2021-03-10 16:04:34,216 - nornir.core.task -    ERROR -      start() - Host 'R3': task 'load_variable' failed with traceback:
Traceback (most recent call last):
  File "/usr/local/lib/python3.9/site-packages/nornir/core/task.py", line 98, in start
    r = self.task(self, **self.params)
  File "/Users/vishalgajjar/Documents/lab/bgp config/bgp_config.py", line 14, in load_variable
    bgp_configuration(task)
  File "/Users/vishalgajjar/Documents/lab/bgp config/bgp_config.py", line 18, in bgp_configuration
    bgp_j2_temp = task.run(
  File "/usr/local/lib/python3.9/site-packages/nornir/core/task.py", line 168, in run
    raise NornirSubTaskError(task=run_task, result=r)
nornir.core.exceptions.NornirSubTaskError: Subtask: Getting iBGP Config (failed)


2021-03-10 16:04:34,216 - nornir.core.task -    ERROR -      start() - Host 'RR-2': task 'Getting iBGP Config' failed with traceback:
Traceback (most recent call last):
  File "/usr/local/lib/python3.9/site-packages/nornir/core/task.py", line 98, in start
    r = self.task(self, **self.params)
TypeError: template_file() missing 1 required positional argument: 'path'

2021-03-10 16:04:34,217 - nornir.core.task -    ERROR -      start() - Host 'R4': task 'Getting iBGP Config' failed with traceback:
Traceback (most recent call last):
  File "/usr/local/lib/python3.9/site-packages/nornir/core/task.py", line 98, in start
    r = self.task(self, **self.params)
TypeError: template_file() missing 1 required positional argument: 'path'

2021-03-10 16:04:34,217 - nornir.core.task -    ERROR -      start() - Host 'RR-1': task 'load_variable' failed with traceback:
Traceback (most recent call last):
  File "/usr/local/lib/python3.9/site-packages/nornir/core/task.py", line 98, in start
    r = self.task(self, **self.params)
  File "/Users/vishalgajjar/Documents/lab/bgp config/bgp_config.py", line 14, in load_variable
    bgp_configuration(task)
  File "/Users/vishalgajjar/Documents/lab/bgp config/bgp_config.py", line 18, in bgp_configuration
    bgp_j2_temp = task.run(
  File "/usr/local/lib/python3.9/site-packages/nornir/core/task.py", line 168, in run
    raise NornirSubTaskError(task=run_task, result=r)
nornir.core.exceptions.NornirSubTaskError: Subtask: Getting iBGP Config (failed)


2021-03-10 16:04:34,217 - nornir.core.task -    ERROR -      start() - Host 'R2': task 'Getting iBGP Config' failed with traceback:
Traceback (most recent call last):
  File "/usr/local/lib/python3.9/site-packages/nornir/core/task.py", line 98, in start
    r = self.task(self, **self.params)
TypeError: template_file() missing 1 required positional argument: 'path'

2021-03-10 16:04:34,218 - nornir.core.task -    ERROR -      start() - Host 'R1': task 'load_variable' failed with traceback:
Traceback (most recent call last):
  File "/usr/local/lib/python3.9/site-packages/nornir/core/task.py", line 98, in start
    r = self.task(self, **self.params)
  File "/Users/vishalgajjar/Documents/lab/bgp config/bgp_config.py", line 14, in load_variable
    bgp_configuration(task)
  File "/Users/vishalgajjar/Documents/lab/bgp config/bgp_config.py", line 18, in bgp_configuration
    bgp_j2_temp = task.run(
  File "/usr/local/lib/python3.9/site-packages/nornir/core/task.py", line 168, in run
    raise NornirSubTaskError(task=run_task, result=r)
nornir.core.exceptions.NornirSubTaskError: Subtask: Getting iBGP Config (failed)


2021-03-10 16:04:34,218 - nornir.core.task -    ERROR -      start() - Host 'R4': task 'load_variable' failed with traceback:
Traceback (most recent call last):
  File "/usr/local/lib/python3.9/site-packages/nornir/core/task.py", line 98, in start
    r = self.task(self, **self.params)
  File "/Users/vishalgajjar/Documents/lab/bgp config/bgp_config.py", line 14, in load_variable
    bgp_configuration(task)
  File "/Users/vishalgajjar/Documents/lab/bgp config/bgp_config.py", line 18, in bgp_configuration
    bgp_j2_temp = task.run(
  File "/usr/local/lib/python3.9/site-packages/nornir/core/task.py", line 168, in run
    raise NornirSubTaskError(task=run_task, result=r)
nornir.core.exceptions.NornirSubTaskError: Subtask: Getting iBGP Config (failed)


2021-03-10 16:04:34,219 - nornir.core.task -    ERROR -      start() - Host 'RR-2': task 'load_variable' failed with traceback:
Traceback (most recent call last):
  File "/usr/local/lib/python3.9/site-packages/nornir/core/task.py", line 98, in start
    r = self.task(self, **self.params)
  File "/Users/vishalgajjar/Documents/lab/bgp config/bgp_config.py", line 14, in load_variable
    bgp_configuration(task)
  File "/Users/vishalgajjar/Documents/lab/bgp config/bgp_config.py", line 18, in bgp_configuration
    bgp_j2_temp = task.run(
  File "/usr/local/lib/python3.9/site-packages/nornir/core/task.py", line 168, in run
    raise NornirSubTaskError(task=run_task, result=r)
nornir.core.exceptions.NornirSubTaskError: Subtask: Getting iBGP Config (failed)


2021-03-10 16:04:34,219 - nornir.core.task -    ERROR -      start() - Host 'R2': task 'load_variable' failed with traceback:
Traceback (most recent call last):
  File "/usr/local/lib/python3.9/site-packages/nornir/core/task.py", line 98, in start
    r = self.task(self, **self.params)
  File "/Users/vishalgajjar/Documents/lab/bgp config/bgp_config.py", line 14, in load_variable
    bgp_configuration(task)
  File "/Users/vishalgajjar/Documents/lab/bgp config/bgp_config.py", line 18, in bgp_configuration
    bgp_j2_temp = task.run(
  File "/usr/local/lib/python3.9/site-packages/nornir/core/task.py", line 168, in run
    raise NornirSubTaskError(task=run_task, result=r)
nornir.core.exceptions.NornirSubTaskError: Subtask: Getting iBGP Config (failed)


2021-03-10 16:13:19,679 -  nornir.core -     INFO -        run() - Running task 'load_variable' with args {} on 6 hosts
2021-03-10 16:13:19,682 - nornir.core.task -    ERROR -      start() - Host 'RR-1': task 'Geting info from Variables' failed with traceback:
Traceback (most recent call last):
  File "/usr/local/lib/python3.9/site-packages/nornir/core/task.py", line 98, in start
    r = self.task(self, **self.params)
  File "/usr/local/lib/python3.9/site-packages/nornir_utils/plugins/tasks/data/load_yaml.py", line 24, in load_yaml
    with open(file, "r") as f:
FileNotFoundError: [Errno 2] No such file or directory: ' ./routers/RR-1.yaml'

2021-03-10 16:13:19,682 - nornir.core.task -    ERROR -      start() - Host 'R1': task 'Geting info from Variables' failed with traceback:
Traceback (most recent call last):
  File "/usr/local/lib/python3.9/site-packages/nornir/core/task.py", line 98, in start
    r = self.task(self, **self.params)
  File "/usr/local/lib/python3.9/site-packages/nornir_utils/plugins/tasks/data/load_yaml.py", line 24, in load_yaml
    with open(file, "r") as f:
FileNotFoundError: [Errno 2] No such file or directory: ' ./routers/R1.yaml'

2021-03-10 16:13:19,683 - nornir.core.task -    ERROR -      start() - Host 'R4': task 'Geting info from Variables' failed with traceback:
Traceback (most recent call last):
  File "/usr/local/lib/python3.9/site-packages/nornir/core/task.py", line 98, in start
    r = self.task(self, **self.params)
  File "/usr/local/lib/python3.9/site-packages/nornir_utils/plugins/tasks/data/load_yaml.py", line 24, in load_yaml
    with open(file, "r") as f:
FileNotFoundError: [Errno 2] No such file or directory: ' ./routers/R4.yaml'

2021-03-10 16:13:19,683 - nornir.core.task -    ERROR -      start() - Host 'RR-2': task 'Geting info from Variables' failed with traceback:
Traceback (most recent call last):
  File "/usr/local/lib/python3.9/site-packages/nornir/core/task.py", line 98, in start
    r = self.task(self, **self.params)
  File "/usr/local/lib/python3.9/site-packages/nornir_utils/plugins/tasks/data/load_yaml.py", line 24, in load_yaml
    with open(file, "r") as f:
FileNotFoundError: [Errno 2] No such file or directory: ' ./routers/RR-2.yaml'

2021-03-10 16:13:19,684 - nornir.core.task -    ERROR -      start() - Host 'R1': task 'load_variable' failed with traceback:
Traceback (most recent call last):
  File "/usr/local/lib/python3.9/site-packages/nornir/core/task.py", line 98, in start
    r = self.task(self, **self.params)
  File "/Users/vishalgajjar/Documents/lab/bgp config/bgp_config.py", line 11, in load_variable
    input_data = task.run(task=load_yaml, name="Geting info from Variables",
  File "/usr/local/lib/python3.9/site-packages/nornir/core/task.py", line 168, in run
    raise NornirSubTaskError(task=run_task, result=r)
nornir.core.exceptions.NornirSubTaskError: Subtask: Geting info from Variables (failed)


2021-03-10 16:13:19,684 - nornir.core.task -    ERROR -      start() - Host 'RR-1': task 'load_variable' failed with traceback:
Traceback (most recent call last):
  File "/usr/local/lib/python3.9/site-packages/nornir/core/task.py", line 98, in start
    r = self.task(self, **self.params)
  File "/Users/vishalgajjar/Documents/lab/bgp config/bgp_config.py", line 11, in load_variable
    input_data = task.run(task=load_yaml, name="Geting info from Variables",
  File "/usr/local/lib/python3.9/site-packages/nornir/core/task.py", line 168, in run
    raise NornirSubTaskError(task=run_task, result=r)
nornir.core.exceptions.NornirSubTaskError: Subtask: Geting info from Variables (failed)


2021-03-10 16:13:19,684 - nornir.core.task -    ERROR -      start() - Host 'R2': task 'Geting info from Variables' failed with traceback:
Traceback (most recent call last):
  File "/usr/local/lib/python3.9/site-packages/nornir/core/task.py", line 98, in start
    r = self.task(self, **self.params)
  File "/usr/local/lib/python3.9/site-packages/nornir_utils/plugins/tasks/data/load_yaml.py", line 24, in load_yaml
    with open(file, "r") as f:
FileNotFoundError: [Errno 2] No such file or directory: ' ./routers/R2.yaml'

2021-03-10 16:13:19,684 - nornir.core.task -    ERROR -      start() - Host 'R3': task 'Geting info from Variables' failed with traceback:
Traceback (most recent call last):
  File "/usr/local/lib/python3.9/site-packages/nornir/core/task.py", line 98, in start
    r = self.task(self, **self.params)
  File "/usr/local/lib/python3.9/site-packages/nornir_utils/plugins/tasks/data/load_yaml.py", line 24, in load_yaml
    with open(file, "r") as f:
FileNotFoundError: [Errno 2] No such file or directory: ' ./routers/R3.yaml'

2021-03-10 16:13:19,684 - nornir.core.task -    ERROR -      start() - Host 'RR-2': task 'load_variable' failed with traceback:
Traceback (most recent call last):
  File "/usr/local/lib/python3.9/site-packages/nornir/core/task.py", line 98, in start
    r = self.task(self, **self.params)
  File "/Users/vishalgajjar/Documents/lab/bgp config/bgp_config.py", line 11, in load_variable
    input_data = task.run(task=load_yaml, name="Geting info from Variables",
  File "/usr/local/lib/python3.9/site-packages/nornir/core/task.py", line 168, in run
    raise NornirSubTaskError(task=run_task, result=r)
nornir.core.exceptions.NornirSubTaskError: Subtask: Geting info from Variables (failed)


2021-03-10 16:13:19,684 - nornir.core.task -    ERROR -      start() - Host 'R4': task 'load_variable' failed with traceback:
Traceback (most recent call last):
  File "/usr/local/lib/python3.9/site-packages/nornir/core/task.py", line 98, in start
    r = self.task(self, **self.params)
  File "/Users/vishalgajjar/Documents/lab/bgp config/bgp_config.py", line 11, in load_variable
    input_data = task.run(task=load_yaml, name="Geting info from Variables",
  File "/usr/local/lib/python3.9/site-packages/nornir/core/task.py", line 168, in run
    raise NornirSubTaskError(task=run_task, result=r)
nornir.core.exceptions.NornirSubTaskError: Subtask: Geting info from Variables (failed)


2021-03-10 16:13:19,685 - nornir.core.task -    ERROR -      start() - Host 'R2': task 'load_variable' failed with traceback:
Traceback (most recent call last):
  File "/usr/local/lib/python3.9/site-packages/nornir/core/task.py", line 98, in start
    r = self.task(self, **self.params)
  File "/Users/vishalgajjar/Documents/lab/bgp config/bgp_config.py", line 11, in load_variable
    input_data = task.run(task=load_yaml, name="Geting info from Variables",
  File "/usr/local/lib/python3.9/site-packages/nornir/core/task.py", line 168, in run
    raise NornirSubTaskError(task=run_task, result=r)
nornir.core.exceptions.NornirSubTaskError: Subtask: Geting info from Variables (failed)


2021-03-10 16:13:19,685 - nornir.core.task -    ERROR -      start() - Host 'R3': task 'load_variable' failed with traceback:
Traceback (most recent call last):
  File "/usr/local/lib/python3.9/site-packages/nornir/core/task.py", line 98, in start
    r = self.task(self, **self.params)
  File "/Users/vishalgajjar/Documents/lab/bgp config/bgp_config.py", line 11, in load_variable
    input_data = task.run(task=load_yaml, name="Geting info from Variables",
  File "/usr/local/lib/python3.9/site-packages/nornir/core/task.py", line 168, in run
    raise NornirSubTaskError(task=run_task, result=r)
nornir.core.exceptions.NornirSubTaskError: Subtask: Geting info from Variables (failed)


2021-03-10 16:14:38,380 -  nornir.core -     INFO -        run() - Running task 'load_variable' with args {} on 6 hosts
2021-03-10 16:14:38,395 - nornir.core.task -    ERROR -      start() - Host 'RR-2': task 'Getting iBGP Config' failed with traceback:
Traceback (most recent call last):
  File "/usr/local/lib/python3.9/site-packages/nornir/core/task.py", line 98, in start
    r = self.task(self, **self.params)
  File "/usr/local/lib/python3.9/site-packages/nornir_jinja2/plugins/tasks/template_file.py", line 42, in template_file
    t = env.get_template(template)
  File "/usr/local/lib/python3.9/site-packages/jinja2/environment.py", line 883, in get_template
    return self._load_template(name, self.make_globals(globals))
  File "/usr/local/lib/python3.9/site-packages/jinja2/environment.py", line 857, in _load_template
    template = self.loader.load(self, name, globals)
  File "/usr/local/lib/python3.9/site-packages/jinja2/loaders.py", line 115, in load
    source, filename, uptodate = self.get_source(environment, name)
  File "/usr/local/lib/python3.9/site-packages/jinja2/loaders.py", line 197, in get_source
    raise TemplateNotFound(template)
jinja2.exceptions.TemplateNotFound: bgp_config.j2

2021-03-10 16:14:38,396 - nornir.core.task -    ERROR -      start() - Host 'R1': task 'Getting iBGP Config' failed with traceback:
Traceback (most recent call last):
  File "/usr/local/lib/python3.9/site-packages/nornir/core/task.py", line 98, in start
    r = self.task(self, **self.params)
  File "/usr/local/lib/python3.9/site-packages/nornir_jinja2/plugins/tasks/template_file.py", line 42, in template_file
    t = env.get_template(template)
  File "/usr/local/lib/python3.9/site-packages/jinja2/environment.py", line 883, in get_template
    return self._load_template(name, self.make_globals(globals))
  File "/usr/local/lib/python3.9/site-packages/jinja2/environment.py", line 857, in _load_template
    template = self.loader.load(self, name, globals)
  File "/usr/local/lib/python3.9/site-packages/jinja2/loaders.py", line 115, in load
    source, filename, uptodate = self.get_source(environment, name)
  File "/usr/local/lib/python3.9/site-packages/jinja2/loaders.py", line 197, in get_source
    raise TemplateNotFound(template)
jinja2.exceptions.TemplateNotFound: bgp_config.j2

2021-03-10 16:14:38,396 - nornir.core.task -    ERROR -      start() - Host 'RR-1': task 'Getting iBGP Config' failed with traceback:
Traceback (most recent call last):
  File "/usr/local/lib/python3.9/site-packages/nornir/core/task.py", line 98, in start
    r = self.task(self, **self.params)
  File "/usr/local/lib/python3.9/site-packages/nornir_jinja2/plugins/tasks/template_file.py", line 42, in template_file
    t = env.get_template(template)
  File "/usr/local/lib/python3.9/site-packages/jinja2/environment.py", line 883, in get_template
    return self._load_template(name, self.make_globals(globals))
  File "/usr/local/lib/python3.9/site-packages/jinja2/environment.py", line 857, in _load_template
    template = self.loader.load(self, name, globals)
  File "/usr/local/lib/python3.9/site-packages/jinja2/loaders.py", line 115, in load
    source, filename, uptodate = self.get_source(environment, name)
  File "/usr/local/lib/python3.9/site-packages/jinja2/loaders.py", line 197, in get_source
    raise TemplateNotFound(template)
jinja2.exceptions.TemplateNotFound: bgp_config.j2

2021-03-10 16:14:38,396 - nornir.core.task -    ERROR -      start() - Host 'R4': task 'Getting iBGP Config' failed with traceback:
Traceback (most recent call last):
  File "/usr/local/lib/python3.9/site-packages/nornir/core/task.py", line 98, in start
    r = self.task(self, **self.params)
  File "/usr/local/lib/python3.9/site-packages/nornir_jinja2/plugins/tasks/template_file.py", line 42, in template_file
    t = env.get_template(template)
  File "/usr/local/lib/python3.9/site-packages/jinja2/environment.py", line 883, in get_template
    return self._load_template(name, self.make_globals(globals))
  File "/usr/local/lib/python3.9/site-packages/jinja2/environment.py", line 857, in _load_template
    template = self.loader.load(self, name, globals)
  File "/usr/local/lib/python3.9/site-packages/jinja2/loaders.py", line 115, in load
    source, filename, uptodate = self.get_source(environment, name)
  File "/usr/local/lib/python3.9/site-packages/jinja2/loaders.py", line 197, in get_source
    raise TemplateNotFound(template)
jinja2.exceptions.TemplateNotFound: bgp_config.j2

2021-03-10 16:14:38,396 - nornir.core.task -    ERROR -      start() - Host 'R3': task 'Getting iBGP Config' failed with traceback:
Traceback (most recent call last):
  File "/usr/local/lib/python3.9/site-packages/nornir/core/task.py", line 98, in start
    r = self.task(self, **self.params)
  File "/usr/local/lib/python3.9/site-packages/nornir_jinja2/plugins/tasks/template_file.py", line 42, in template_file
    t = env.get_template(template)
  File "/usr/local/lib/python3.9/site-packages/jinja2/environment.py", line 883, in get_template
    return self._load_template(name, self.make_globals(globals))
  File "/usr/local/lib/python3.9/site-packages/jinja2/environment.py", line 857, in _load_template
    template = self.loader.load(self, name, globals)
  File "/usr/local/lib/python3.9/site-packages/jinja2/loaders.py", line 115, in load
    source, filename, uptodate = self.get_source(environment, name)
  File "/usr/local/lib/python3.9/site-packages/jinja2/loaders.py", line 197, in get_source
    raise TemplateNotFound(template)
jinja2.exceptions.TemplateNotFound: bgp_config.j2

2021-03-10 16:14:38,396 - nornir.core.task -    ERROR -      start() - Host 'R2': task 'Getting iBGP Config' failed with traceback:
Traceback (most recent call last):
  File "/usr/local/lib/python3.9/site-packages/nornir/core/task.py", line 98, in start
    r = self.task(self, **self.params)
  File "/usr/local/lib/python3.9/site-packages/nornir_jinja2/plugins/tasks/template_file.py", line 42, in template_file
    t = env.get_template(template)
  File "/usr/local/lib/python3.9/site-packages/jinja2/environment.py", line 883, in get_template
    return self._load_template(name, self.make_globals(globals))
  File "/usr/local/lib/python3.9/site-packages/jinja2/environment.py", line 857, in _load_template
    template = self.loader.load(self, name, globals)
  File "/usr/local/lib/python3.9/site-packages/jinja2/loaders.py", line 115, in load
    source, filename, uptodate = self.get_source(environment, name)
  File "/usr/local/lib/python3.9/site-packages/jinja2/loaders.py", line 197, in get_source
    raise TemplateNotFound(template)
jinja2.exceptions.TemplateNotFound: bgp_config.j2

2021-03-10 16:14:38,397 - nornir.core.task -    ERROR -      start() - Host 'R1': task 'load_variable' failed with traceback:
Traceback (most recent call last):
  File "/usr/local/lib/python3.9/site-packages/nornir/core/task.py", line 98, in start
    r = self.task(self, **self.params)
  File "/Users/vishalgajjar/Documents/lab/bgp config/bgp_config.py", line 14, in load_variable
    bgp_configuration(task)
  File "/Users/vishalgajjar/Documents/lab/bgp config/bgp_config.py", line 18, in bgp_configuration
    bgp_j2_temp = task.run(
  File "/usr/local/lib/python3.9/site-packages/nornir/core/task.py", line 168, in run
    raise NornirSubTaskError(task=run_task, result=r)
nornir.core.exceptions.NornirSubTaskError: Subtask: Getting iBGP Config (failed)


2021-03-10 16:14:38,398 - nornir.core.task -    ERROR -      start() - Host 'RR-1': task 'load_variable' failed with traceback:
Traceback (most recent call last):
  File "/usr/local/lib/python3.9/site-packages/nornir/core/task.py", line 98, in start
    r = self.task(self, **self.params)
  File "/Users/vishalgajjar/Documents/lab/bgp config/bgp_config.py", line 14, in load_variable
    bgp_configuration(task)
  File "/Users/vishalgajjar/Documents/lab/bgp config/bgp_config.py", line 18, in bgp_configuration
    bgp_j2_temp = task.run(
  File "/usr/local/lib/python3.9/site-packages/nornir/core/task.py", line 168, in run
    raise NornirSubTaskError(task=run_task, result=r)
nornir.core.exceptions.NornirSubTaskError: Subtask: Getting iBGP Config (failed)


2021-03-10 16:14:38,398 - nornir.core.task -    ERROR -      start() - Host 'RR-2': task 'load_variable' failed with traceback:
Traceback (most recent call last):
  File "/usr/local/lib/python3.9/site-packages/nornir/core/task.py", line 98, in start
    r = self.task(self, **self.params)
  File "/Users/vishalgajjar/Documents/lab/bgp config/bgp_config.py", line 14, in load_variable
    bgp_configuration(task)
  File "/Users/vishalgajjar/Documents/lab/bgp config/bgp_config.py", line 18, in bgp_configuration
    bgp_j2_temp = task.run(
  File "/usr/local/lib/python3.9/site-packages/nornir/core/task.py", line 168, in run
    raise NornirSubTaskError(task=run_task, result=r)
nornir.core.exceptions.NornirSubTaskError: Subtask: Getting iBGP Config (failed)


2021-03-10 16:14:38,399 - nornir.core.task -    ERROR -      start() - Host 'R4': task 'load_variable' failed with traceback:
Traceback (most recent call last):
  File "/usr/local/lib/python3.9/site-packages/nornir/core/task.py", line 98, in start
    r = self.task(self, **self.params)
  File "/Users/vishalgajjar/Documents/lab/bgp config/bgp_config.py", line 14, in load_variable
    bgp_configuration(task)
  File "/Users/vishalgajjar/Documents/lab/bgp config/bgp_config.py", line 18, in bgp_configuration
    bgp_j2_temp = task.run(
  File "/usr/local/lib/python3.9/site-packages/nornir/core/task.py", line 168, in run
    raise NornirSubTaskError(task=run_task, result=r)
nornir.core.exceptions.NornirSubTaskError: Subtask: Getting iBGP Config (failed)


2021-03-10 16:14:38,399 - nornir.core.task -    ERROR -      start() - Host 'R3': task 'load_variable' failed with traceback:
Traceback (most recent call last):
  File "/usr/local/lib/python3.9/site-packages/nornir/core/task.py", line 98, in start
    r = self.task(self, **self.params)
  File "/Users/vishalgajjar/Documents/lab/bgp config/bgp_config.py", line 14, in load_variable
    bgp_configuration(task)
  File "/Users/vishalgajjar/Documents/lab/bgp config/bgp_config.py", line 18, in bgp_configuration
    bgp_j2_temp = task.run(
  File "/usr/local/lib/python3.9/site-packages/nornir/core/task.py", line 168, in run
    raise NornirSubTaskError(task=run_task, result=r)
nornir.core.exceptions.NornirSubTaskError: Subtask: Getting iBGP Config (failed)


2021-03-10 16:14:38,399 - nornir.core.task -    ERROR -      start() - Host 'R2': task 'load_variable' failed with traceback:
Traceback (most recent call last):
  File "/usr/local/lib/python3.9/site-packages/nornir/core/task.py", line 98, in start
    r = self.task(self, **self.params)
  File "/Users/vishalgajjar/Documents/lab/bgp config/bgp_config.py", line 14, in load_variable
    bgp_configuration(task)
  File "/Users/vishalgajjar/Documents/lab/bgp config/bgp_config.py", line 18, in bgp_configuration
    bgp_j2_temp = task.run(
  File "/usr/local/lib/python3.9/site-packages/nornir/core/task.py", line 168, in run
    raise NornirSubTaskError(task=run_task, result=r)
nornir.core.exceptions.NornirSubTaskError: Subtask: Getting iBGP Config (failed)


2021-03-10 16:15:27,864 -  nornir.core -     INFO -        run() - Running task 'load_variable' with args {} on 6 hosts
2021-03-10 16:15:27,938 - nornir.core.task -    ERROR -      start() - Host 'R4': task 'Getting iBGP Config' failed with traceback:
Traceback (most recent call last):
  File "/usr/local/lib/python3.9/site-packages/jinja2/environment.py", line 1088, in render
    return concat(self.root_render_func(self.new_context(vars)))
  File "bgp_config.j2", line 18, in root
  File "/usr/local/lib/python3.9/site-packages/jinja2/environment.py", line 471, in getattr
    return getattr(obj, attribute)
  File "/usr/local/lib/python3.9/site-packages/jinja2/runtime.py", line 753, in __getattr__
    return self._fail_with_undefined_error()
  File "/usr/local/lib/python3.9/site-packages/jinja2/runtime.py", line 747, in _fail_with_undefined_error
    raise self._undefined_exception(self._undefined_message)
jinja2.exceptions.UndefinedError: 'None' has no attribute 'bgp'

During handling of the above exception, another exception occurred:

Traceback (most recent call last):
  File "/usr/local/lib/python3.9/site-packages/nornir/core/task.py", line 98, in start
    r = self.task(self, **self.params)
  File "/usr/local/lib/python3.9/site-packages/nornir_jinja2/plugins/tasks/template_file.py", line 43, in template_file
    text = t.render(host=task.host, **kwargs)
  File "/usr/local/lib/python3.9/site-packages/jinja2/environment.py", line 1090, in render
    self.environment.handle_exception()
  File "/usr/local/lib/python3.9/site-packages/jinja2/environment.py", line 830, in handle_exception
    from .debug import rewrite_traceback_stack
ImportError: cannot import name 'rewrite_traceback_stack' from partially initialized module 'jinja2.debug' (most likely due to a circular import) (/usr/local/lib/python3.9/site-packages/jinja2/debug.py)

2021-03-10 16:15:27,939 - nornir.core.task -    ERROR -      start() - Host 'RR-2': task 'Getting iBGP Config' failed with traceback:
Traceback (most recent call last):
  File "/usr/local/lib/python3.9/site-packages/jinja2/environment.py", line 1088, in render
    return concat(self.root_render_func(self.new_context(vars)))
  File "bgp_config.j2", line 20, in root
  File "/usr/local/lib/python3.9/site-packages/jinja2/runtime.py", line 747, in _fail_with_undefined_error
    raise self._undefined_exception(self._undefined_message)
jinja2.exceptions.UndefinedError: 'dict object' has no attribute 'router'

During handling of the above exception, another exception occurred:

Traceback (most recent call last):
  File "/usr/local/lib/python3.9/site-packages/nornir/core/task.py", line 98, in start
    r = self.task(self, **self.params)
  File "/usr/local/lib/python3.9/site-packages/nornir_jinja2/plugins/tasks/template_file.py", line 43, in template_file
    text = t.render(host=task.host, **kwargs)
  File "/usr/local/lib/python3.9/site-packages/jinja2/environment.py", line 1090, in render
    self.environment.handle_exception()
  File "/usr/local/lib/python3.9/site-packages/jinja2/environment.py", line 830, in handle_exception
    from .debug import rewrite_traceback_stack
ImportError: cannot import name 'rewrite_traceback_stack' from partially initialized module 'jinja2.debug' (most likely due to a circular import) (/usr/local/lib/python3.9/site-packages/jinja2/debug.py)

2021-03-10 16:15:27,940 - nornir.core.task -    ERROR -      start() - Host 'R3': task 'Getting iBGP Config' failed with traceback:
Traceback (most recent call last):
  File "/usr/local/lib/python3.9/site-packages/jinja2/environment.py", line 1088, in render
    return concat(self.root_render_func(self.new_context(vars)))
  File "bgp_config.j2", line 18, in root
  File "/usr/local/lib/python3.9/site-packages/jinja2/environment.py", line 471, in getattr
    return getattr(obj, attribute)
  File "/usr/local/lib/python3.9/site-packages/jinja2/runtime.py", line 753, in __getattr__
    return self._fail_with_undefined_error()
  File "/usr/local/lib/python3.9/site-packages/jinja2/runtime.py", line 747, in _fail_with_undefined_error
    raise self._undefined_exception(self._undefined_message)
jinja2.exceptions.UndefinedError: 'None' has no attribute 'bgp'

During handling of the above exception, another exception occurred:

Traceback (most recent call last):
  File "/usr/local/lib/python3.9/site-packages/nornir/core/task.py", line 98, in start
    r = self.task(self, **self.params)
  File "/usr/local/lib/python3.9/site-packages/nornir_jinja2/plugins/tasks/template_file.py", line 43, in template_file
    text = t.render(host=task.host, **kwargs)
  File "/usr/local/lib/python3.9/site-packages/jinja2/environment.py", line 1090, in render
    self.environment.handle_exception()
  File "/usr/local/lib/python3.9/site-packages/jinja2/environment.py", line 830, in handle_exception
    from .debug import rewrite_traceback_stack
ImportError: cannot import name 'rewrite_traceback_stack' from partially initialized module 'jinja2.debug' (most likely due to a circular import) (/usr/local/lib/python3.9/site-packages/jinja2/debug.py)

2021-03-10 16:15:27,941 - nornir.core.task -    ERROR -      start() - Host 'R1': task 'Getting iBGP Config' failed with traceback:
Traceback (most recent call last):
  File "/usr/local/lib/python3.9/site-packages/jinja2/environment.py", line 1088, in render
    return concat(self.root_render_func(self.new_context(vars)))
  File "bgp_config.j2", line 18, in root
  File "/usr/local/lib/python3.9/site-packages/jinja2/environment.py", line 471, in getattr
    return getattr(obj, attribute)
  File "/usr/local/lib/python3.9/site-packages/jinja2/runtime.py", line 753, in __getattr__
    return self._fail_with_undefined_error()
  File "/usr/local/lib/python3.9/site-packages/jinja2/runtime.py", line 747, in _fail_with_undefined_error
    raise self._undefined_exception(self._undefined_message)
jinja2.exceptions.UndefinedError: 'None' has no attribute 'bgp'

During handling of the above exception, another exception occurred:

Traceback (most recent call last):
  File "/usr/local/lib/python3.9/site-packages/nornir/core/task.py", line 98, in start
    r = self.task(self, **self.params)
  File "/usr/local/lib/python3.9/site-packages/nornir_jinja2/plugins/tasks/template_file.py", line 43, in template_file
    text = t.render(host=task.host, **kwargs)
  File "/usr/local/lib/python3.9/site-packages/jinja2/environment.py", line 1090, in render
    self.environment.handle_exception()
  File "/usr/local/lib/python3.9/site-packages/jinja2/environment.py", line 830, in handle_exception
    from .debug import rewrite_traceback_stack
ImportError: cannot import name 'rewrite_traceback_stack' from partially initialized module 'jinja2.debug' (most likely due to a circular import) (/usr/local/lib/python3.9/site-packages/jinja2/debug.py)

2021-03-10 16:15:27,944 - nornir.core.task -    ERROR -      start() - Host 'R1': task 'load_variable' failed with traceback:
Traceback (most recent call last):
  File "/usr/local/lib/python3.9/site-packages/nornir/core/task.py", line 98, in start
    r = self.task(self, **self.params)
  File "/Users/vishalgajjar/Documents/lab/bgp config/bgp_config.py", line 14, in load_variable
    bgp_configuration(task)
  File "/Users/vishalgajjar/Documents/lab/bgp config/bgp_config.py", line 18, in bgp_configuration
    bgp_j2_temp = task.run(
  File "/usr/local/lib/python3.9/site-packages/nornir/core/task.py", line 168, in run
    raise NornirSubTaskError(task=run_task, result=r)
nornir.core.exceptions.NornirSubTaskError: Subtask: Getting iBGP Config (failed)


2021-03-10 16:15:27,941 - nornir.core.task -    ERROR -      start() - Host 'R4': task 'load_variable' failed with traceback:
Traceback (most recent call last):
  File "/usr/local/lib/python3.9/site-packages/nornir/core/task.py", line 98, in start
    r = self.task(self, **self.params)
  File "/Users/vishalgajjar/Documents/lab/bgp config/bgp_config.py", line 14, in load_variable
    bgp_configuration(task)
  File "/Users/vishalgajjar/Documents/lab/bgp config/bgp_config.py", line 18, in bgp_configuration
    bgp_j2_temp = task.run(
  File "/usr/local/lib/python3.9/site-packages/nornir/core/task.py", line 168, in run
    raise NornirSubTaskError(task=run_task, result=r)
nornir.core.exceptions.NornirSubTaskError: Subtask: Getting iBGP Config (failed)


2021-03-10 16:15:27,942 - nornir.core.task -    ERROR -      start() - Host 'RR-1': task 'Getting iBGP Config' failed with traceback:
Traceback (most recent call last):
  File "/usr/local/lib/python3.9/site-packages/nornir/core/task.py", line 98, in start
    r = self.task(self, **self.params)
  File "/usr/local/lib/python3.9/site-packages/nornir_jinja2/plugins/tasks/template_file.py", line 43, in template_file
    text = t.render(host=task.host, **kwargs)
  File "/usr/local/lib/python3.9/site-packages/jinja2/environment.py", line 1090, in render
    self.environment.handle_exception()
  File "/usr/local/lib/python3.9/site-packages/jinja2/environment.py", line 832, in handle_exception
    reraise(*rewrite_traceback_stack(source=source))
  File "/usr/local/lib/python3.9/site-packages/jinja2/_compat.py", line 28, in reraise
    raise value.with_traceback(tb)
  File "bgp_config.j2", line 2, in top-level template code
    bgp router-id {{host.conf.bgp.router-id}}
jinja2.exceptions.UndefinedError: 'dict object' has no attribute 'router'

2021-03-10 16:15:27,942 - nornir.core.task -    ERROR -      start() - Host 'RR-2': task 'load_variable' failed with traceback:
Traceback (most recent call last):
  File "/usr/local/lib/python3.9/site-packages/nornir/core/task.py", line 98, in start
    r = self.task(self, **self.params)
  File "/Users/vishalgajjar/Documents/lab/bgp config/bgp_config.py", line 14, in load_variable
    bgp_configuration(task)
  File "/Users/vishalgajjar/Documents/lab/bgp config/bgp_config.py", line 18, in bgp_configuration
    bgp_j2_temp = task.run(
  File "/usr/local/lib/python3.9/site-packages/nornir/core/task.py", line 168, in run
    raise NornirSubTaskError(task=run_task, result=r)
nornir.core.exceptions.NornirSubTaskError: Subtask: Getting iBGP Config (failed)


2021-03-10 16:15:27,946 - nornir.core.task -    ERROR -      start() - Host 'R3': task 'load_variable' failed with traceback:
Traceback (most recent call last):
  File "/usr/local/lib/python3.9/site-packages/nornir/core/task.py", line 98, in start
    r = self.task(self, **self.params)
  File "/Users/vishalgajjar/Documents/lab/bgp config/bgp_config.py", line 14, in load_variable
    bgp_configuration(task)
  File "/Users/vishalgajjar/Documents/lab/bgp config/bgp_config.py", line 18, in bgp_configuration
    bgp_j2_temp = task.run(
  File "/usr/local/lib/python3.9/site-packages/nornir/core/task.py", line 168, in run
    raise NornirSubTaskError(task=run_task, result=r)
nornir.core.exceptions.NornirSubTaskError: Subtask: Getting iBGP Config (failed)


2021-03-10 16:15:27,946 - nornir.core.task -    ERROR -      start() - Host 'RR-1': task 'load_variable' failed with traceback:
Traceback (most recent call last):
  File "/usr/local/lib/python3.9/site-packages/nornir/core/task.py", line 98, in start
    r = self.task(self, **self.params)
  File "/Users/vishalgajjar/Documents/lab/bgp config/bgp_config.py", line 14, in load_variable
    bgp_configuration(task)
  File "/Users/vishalgajjar/Documents/lab/bgp config/bgp_config.py", line 18, in bgp_configuration
    bgp_j2_temp = task.run(
  File "/usr/local/lib/python3.9/site-packages/nornir/core/task.py", line 168, in run
    raise NornirSubTaskError(task=run_task, result=r)
nornir.core.exceptions.NornirSubTaskError: Subtask: Getting iBGP Config (failed)


2021-03-10 16:15:27,943 - nornir.core.task -    ERROR -      start() - Host 'R2': task 'Getting iBGP Config' failed with traceback:
Traceback (most recent call last):
  File "/usr/local/lib/python3.9/site-packages/nornir/core/task.py", line 98, in start
    r = self.task(self, **self.params)
  File "/usr/local/lib/python3.9/site-packages/nornir_jinja2/plugins/tasks/template_file.py", line 43, in template_file
    text = t.render(host=task.host, **kwargs)
  File "/usr/local/lib/python3.9/site-packages/jinja2/environment.py", line 1090, in render
    self.environment.handle_exception()
  File "/usr/local/lib/python3.9/site-packages/jinja2/environment.py", line 832, in handle_exception
    reraise(*rewrite_traceback_stack(source=source))
  File "/usr/local/lib/python3.9/site-packages/jinja2/_compat.py", line 28, in reraise
    raise value.with_traceback(tb)
  File "bgp_config.j2", line 1, in top-level template code
    router bgp {{host.conf.bgp.asn}}
  File "/usr/local/lib/python3.9/site-packages/jinja2/environment.py", line 471, in getattr
    return getattr(obj, attribute)
jinja2.exceptions.UndefinedError: 'None' has no attribute 'bgp'

2021-03-10 16:15:27,947 - nornir.core.task -    ERROR -      start() - Host 'R2': task 'load_variable' failed with traceback:
Traceback (most recent call last):
  File "/usr/local/lib/python3.9/site-packages/nornir/core/task.py", line 98, in start
    r = self.task(self, **self.params)
  File "/Users/vishalgajjar/Documents/lab/bgp config/bgp_config.py", line 14, in load_variable
    bgp_configuration(task)
  File "/Users/vishalgajjar/Documents/lab/bgp config/bgp_config.py", line 18, in bgp_configuration
    bgp_j2_temp = task.run(
  File "/usr/local/lib/python3.9/site-packages/nornir/core/task.py", line 168, in run
    raise NornirSubTaskError(task=run_task, result=r)
nornir.core.exceptions.NornirSubTaskError: Subtask: Getting iBGP Config (failed)


2021-03-10 16:18:14,829 -  nornir.core -     INFO -        run() - Running task 'load_variable' with args {} on 6 hosts
2021-03-10 16:18:14,907 - nornir.core.task -    ERROR -      start() - Host 'RR-2': task 'Getting iBGP Config' failed with traceback:
Traceback (most recent call last):
  File "/usr/local/lib/python3.9/site-packages/nornir/core/task.py", line 98, in start
    r = self.task(self, **self.params)
  File "/usr/local/lib/python3.9/site-packages/nornir_jinja2/plugins/tasks/template_file.py", line 43, in template_file
    text = t.render(host=task.host, **kwargs)
  File "/usr/local/lib/python3.9/site-packages/jinja2/environment.py", line 1090, in render
    self.environment.handle_exception()
  File "/usr/local/lib/python3.9/site-packages/jinja2/environment.py", line 832, in handle_exception
    reraise(*rewrite_traceback_stack(source=source))
  File "/usr/local/lib/python3.9/site-packages/jinja2/_compat.py", line 28, in reraise
    raise value.with_traceback(tb)
  File "bgp_config.j2", line 3, in top-level template code
    {% if host.conf.bgp.route-reflector == True %}
jinja2.exceptions.UndefinedError: 'dict object' has no attribute 'route'

2021-03-10 16:18:14,907 - nornir.core.task -    ERROR -      start() - Host 'R1': task 'Getting iBGP Config' failed with traceback:
Traceback (most recent call last):
  File "/usr/local/lib/python3.9/site-packages/nornir/core/task.py", line 98, in start
    r = self.task(self, **self.params)
  File "/usr/local/lib/python3.9/site-packages/nornir_jinja2/plugins/tasks/template_file.py", line 43, in template_file
    text = t.render(host=task.host, **kwargs)
  File "/usr/local/lib/python3.9/site-packages/jinja2/environment.py", line 1090, in render
    self.environment.handle_exception()
  File "/usr/local/lib/python3.9/site-packages/jinja2/environment.py", line 832, in handle_exception
    reraise(*rewrite_traceback_stack(source=source))
  File "/usr/local/lib/python3.9/site-packages/jinja2/_compat.py", line 28, in reraise
    raise value.with_traceback(tb)
  File "bgp_config.j2", line 3, in top-level template code
    {% if host.conf.bgp.route-reflector == True %}
jinja2.exceptions.UndefinedError: 'dict object' has no attribute 'route'

2021-03-10 16:18:14,907 - nornir.core.task -    ERROR -      start() - Host 'R2': task 'Getting iBGP Config' failed with traceback:
Traceback (most recent call last):
  File "/usr/local/lib/python3.9/site-packages/nornir/core/task.py", line 98, in start
    r = self.task(self, **self.params)
  File "/usr/local/lib/python3.9/site-packages/nornir_jinja2/plugins/tasks/template_file.py", line 43, in template_file
    text = t.render(host=task.host, **kwargs)
  File "/usr/local/lib/python3.9/site-packages/jinja2/environment.py", line 1090, in render
    self.environment.handle_exception()
  File "/usr/local/lib/python3.9/site-packages/jinja2/environment.py", line 832, in handle_exception
    reraise(*rewrite_traceback_stack(source=source))
  File "/usr/local/lib/python3.9/site-packages/jinja2/_compat.py", line 28, in reraise
    raise value.with_traceback(tb)
  File "bgp_config.j2", line 3, in top-level template code
    {% if host.conf.bgp.route-reflector == True %}
jinja2.exceptions.UndefinedError: 'dict object' has no attribute 'route'

2021-03-10 16:18:14,908 - nornir.core.task -    ERROR -      start() - Host 'RR-1': task 'Getting iBGP Config' failed with traceback:
Traceback (most recent call last):
  File "/usr/local/lib/python3.9/site-packages/nornir/core/task.py", line 98, in start
    r = self.task(self, **self.params)
  File "/usr/local/lib/python3.9/site-packages/nornir_jinja2/plugins/tasks/template_file.py", line 43, in template_file
    text = t.render(host=task.host, **kwargs)
  File "/usr/local/lib/python3.9/site-packages/jinja2/environment.py", line 1090, in render
    self.environment.handle_exception()
  File "/usr/local/lib/python3.9/site-packages/jinja2/environment.py", line 832, in handle_exception
    reraise(*rewrite_traceback_stack(source=source))
  File "/usr/local/lib/python3.9/site-packages/jinja2/_compat.py", line 28, in reraise
    raise value.with_traceback(tb)
  File "bgp_config.j2", line 2, in top-level template code
    bgp router-id {{host.conf.bgp.router_id}}
jinja2.exceptions.UndefinedError: 'dict object' has no attribute 'router_id'

2021-03-10 16:18:14,908 - nornir.core.task -    ERROR -      start() - Host 'R3': task 'Getting iBGP Config' failed with traceback:
Traceback (most recent call last):
  File "/usr/local/lib/python3.9/site-packages/nornir/core/task.py", line 98, in start
    r = self.task(self, **self.params)
  File "/usr/local/lib/python3.9/site-packages/nornir_jinja2/plugins/tasks/template_file.py", line 43, in template_file
    text = t.render(host=task.host, **kwargs)
  File "/usr/local/lib/python3.9/site-packages/jinja2/environment.py", line 1090, in render
    self.environment.handle_exception()
  File "/usr/local/lib/python3.9/site-packages/jinja2/environment.py", line 832, in handle_exception
    reraise(*rewrite_traceback_stack(source=source))
  File "/usr/local/lib/python3.9/site-packages/jinja2/_compat.py", line 28, in reraise
    raise value.with_traceback(tb)
  File "bgp_config.j2", line 3, in top-level template code
    {% if host.conf.bgp.route-reflector == True %}
jinja2.exceptions.UndefinedError: 'dict object' has no attribute 'route'

2021-03-10 16:18:14,908 - nornir.core.task -    ERROR -      start() - Host 'R4': task 'Getting iBGP Config' failed with traceback:
Traceback (most recent call last):
  File "/usr/local/lib/python3.9/site-packages/nornir/core/task.py", line 98, in start
    r = self.task(self, **self.params)
  File "/usr/local/lib/python3.9/site-packages/nornir_jinja2/plugins/tasks/template_file.py", line 43, in template_file
    text = t.render(host=task.host, **kwargs)
  File "/usr/local/lib/python3.9/site-packages/jinja2/environment.py", line 1090, in render
    self.environment.handle_exception()
  File "/usr/local/lib/python3.9/site-packages/jinja2/environment.py", line 832, in handle_exception
    reraise(*rewrite_traceback_stack(source=source))
  File "/usr/local/lib/python3.9/site-packages/jinja2/_compat.py", line 28, in reraise
    raise value.with_traceback(tb)
  File "bgp_config.j2", line 3, in top-level template code
    {% if host.conf.bgp.route-reflector == True %}
jinja2.exceptions.UndefinedError: 'dict object' has no attribute 'route'

2021-03-10 16:18:14,909 - nornir.core.task -    ERROR -      start() - Host 'RR-2': task 'load_variable' failed with traceback:
Traceback (most recent call last):
  File "/usr/local/lib/python3.9/site-packages/nornir/core/task.py", line 98, in start
    r = self.task(self, **self.params)
  File "/Users/vishalgajjar/Documents/lab/bgp config/bgp_config.py", line 14, in load_variable
    bgp_configuration(task)
  File "/Users/vishalgajjar/Documents/lab/bgp config/bgp_config.py", line 18, in bgp_configuration
    bgp_j2_temp = task.run(
  File "/usr/local/lib/python3.9/site-packages/nornir/core/task.py", line 168, in run
    raise NornirSubTaskError(task=run_task, result=r)
nornir.core.exceptions.NornirSubTaskError: Subtask: Getting iBGP Config (failed)


2021-03-10 16:18:14,909 - nornir.core.task -    ERROR -      start() - Host 'R2': task 'load_variable' failed with traceback:
Traceback (most recent call last):
  File "/usr/local/lib/python3.9/site-packages/nornir/core/task.py", line 98, in start
    r = self.task(self, **self.params)
  File "/Users/vishalgajjar/Documents/lab/bgp config/bgp_config.py", line 14, in load_variable
    bgp_configuration(task)
  File "/Users/vishalgajjar/Documents/lab/bgp config/bgp_config.py", line 18, in bgp_configuration
    bgp_j2_temp = task.run(
  File "/usr/local/lib/python3.9/site-packages/nornir/core/task.py", line 168, in run
    raise NornirSubTaskError(task=run_task, result=r)
nornir.core.exceptions.NornirSubTaskError: Subtask: Getting iBGP Config (failed)


2021-03-10 16:18:14,909 - nornir.core.task -    ERROR -      start() - Host 'R3': task 'load_variable' failed with traceback:
Traceback (most recent call last):
  File "/usr/local/lib/python3.9/site-packages/nornir/core/task.py", line 98, in start
    r = self.task(self, **self.params)
  File "/Users/vishalgajjar/Documents/lab/bgp config/bgp_config.py", line 14, in load_variable
    bgp_configuration(task)
  File "/Users/vishalgajjar/Documents/lab/bgp config/bgp_config.py", line 18, in bgp_configuration
    bgp_j2_temp = task.run(
  File "/usr/local/lib/python3.9/site-packages/nornir/core/task.py", line 168, in run
    raise NornirSubTaskError(task=run_task, result=r)
nornir.core.exceptions.NornirSubTaskError: Subtask: Getting iBGP Config (failed)


2021-03-10 16:18:14,909 - nornir.core.task -    ERROR -      start() - Host 'R4': task 'load_variable' failed with traceback:
Traceback (most recent call last):
  File "/usr/local/lib/python3.9/site-packages/nornir/core/task.py", line 98, in start
    r = self.task(self, **self.params)
  File "/Users/vishalgajjar/Documents/lab/bgp config/bgp_config.py", line 14, in load_variable
    bgp_configuration(task)
  File "/Users/vishalgajjar/Documents/lab/bgp config/bgp_config.py", line 18, in bgp_configuration
    bgp_j2_temp = task.run(
  File "/usr/local/lib/python3.9/site-packages/nornir/core/task.py", line 168, in run
    raise NornirSubTaskError(task=run_task, result=r)
nornir.core.exceptions.NornirSubTaskError: Subtask: Getting iBGP Config (failed)


2021-03-10 16:18:14,909 - nornir.core.task -    ERROR -      start() - Host 'R1': task 'load_variable' failed with traceback:
Traceback (most recent call last):
  File "/usr/local/lib/python3.9/site-packages/nornir/core/task.py", line 98, in start
    r = self.task(self, **self.params)
  File "/Users/vishalgajjar/Documents/lab/bgp config/bgp_config.py", line 14, in load_variable
    bgp_configuration(task)
  File "/Users/vishalgajjar/Documents/lab/bgp config/bgp_config.py", line 18, in bgp_configuration
    bgp_j2_temp = task.run(
  File "/usr/local/lib/python3.9/site-packages/nornir/core/task.py", line 168, in run
    raise NornirSubTaskError(task=run_task, result=r)
nornir.core.exceptions.NornirSubTaskError: Subtask: Getting iBGP Config (failed)


2021-03-10 16:18:14,909 - nornir.core.task -    ERROR -      start() - Host 'RR-1': task 'load_variable' failed with traceback:
Traceback (most recent call last):
  File "/usr/local/lib/python3.9/site-packages/nornir/core/task.py", line 98, in start
    r = self.task(self, **self.params)
  File "/Users/vishalgajjar/Documents/lab/bgp config/bgp_config.py", line 14, in load_variable
    bgp_configuration(task)
  File "/Users/vishalgajjar/Documents/lab/bgp config/bgp_config.py", line 18, in bgp_configuration
    bgp_j2_temp = task.run(
  File "/usr/local/lib/python3.9/site-packages/nornir/core/task.py", line 168, in run
    raise NornirSubTaskError(task=run_task, result=r)
nornir.core.exceptions.NornirSubTaskError: Subtask: Getting iBGP Config (failed)


2021-03-10 16:21:05,112 -  nornir.core -     INFO -        run() - Running task 'load_variable' with args {} on 6 hosts
2021-03-10 16:21:05,183 - nornir.core.task -    ERROR -      start() - Host 'R2': task 'Getting iBGP Config' failed with traceback:
Traceback (most recent call last):
  File "/usr/local/lib/python3.9/site-packages/jinja2/environment.py", line 1088, in render
    return concat(self.root_render_func(self.new_context(vars)))
  File "bgp_config.j2", line 20, in root
  File "/usr/local/lib/python3.9/site-packages/jinja2/runtime.py", line 747, in _fail_with_undefined_error
    raise self._undefined_exception(self._undefined_message)
jinja2.exceptions.UndefinedError: 'dict object' has no attribute 'route'

During handling of the above exception, another exception occurred:

Traceback (most recent call last):
  File "/usr/local/lib/python3.9/site-packages/nornir/core/task.py", line 98, in start
    r = self.task(self, **self.params)
  File "/usr/local/lib/python3.9/site-packages/nornir_jinja2/plugins/tasks/template_file.py", line 43, in template_file
    text = t.render(host=task.host, **kwargs)
  File "/usr/local/lib/python3.9/site-packages/jinja2/environment.py", line 1090, in render
    self.environment.handle_exception()
  File "/usr/local/lib/python3.9/site-packages/jinja2/environment.py", line 830, in handle_exception
    from .debug import rewrite_traceback_stack
ImportError: cannot import name 'rewrite_traceback_stack' from partially initialized module 'jinja2.debug' (most likely due to a circular import) (/usr/local/lib/python3.9/site-packages/jinja2/debug.py)

2021-03-10 16:21:05,184 - nornir.core.task -    ERROR -      start() - Host 'R4': task 'Getting iBGP Config' failed with traceback:
Traceback (most recent call last):
  File "/usr/local/lib/python3.9/site-packages/jinja2/environment.py", line 1088, in render
    return concat(self.root_render_func(self.new_context(vars)))
  File "bgp_config.j2", line 20, in root
  File "/usr/local/lib/python3.9/site-packages/jinja2/runtime.py", line 747, in _fail_with_undefined_error
    raise self._undefined_exception(self._undefined_message)
jinja2.exceptions.UndefinedError: 'dict object' has no attribute 'route'

During handling of the above exception, another exception occurred:

Traceback (most recent call last):
  File "/usr/local/lib/python3.9/site-packages/nornir/core/task.py", line 98, in start
    r = self.task(self, **self.params)
  File "/usr/local/lib/python3.9/site-packages/nornir_jinja2/plugins/tasks/template_file.py", line 43, in template_file
    text = t.render(host=task.host, **kwargs)
  File "/usr/local/lib/python3.9/site-packages/jinja2/environment.py", line 1090, in render
    self.environment.handle_exception()
  File "/usr/local/lib/python3.9/site-packages/jinja2/environment.py", line 830, in handle_exception
    from .debug import rewrite_traceback_stack
ImportError: cannot import name 'rewrite_traceback_stack' from partially initialized module 'jinja2.debug' (most likely due to a circular import) (/usr/local/lib/python3.9/site-packages/jinja2/debug.py)

2021-03-10 16:21:05,184 - nornir.core.task -    ERROR -      start() - Host 'RR-1': task 'Getting iBGP Config' failed with traceback:
Traceback (most recent call last):
  File "/usr/local/lib/python3.9/site-packages/jinja2/environment.py", line 1088, in render
    return concat(self.root_render_func(self.new_context(vars)))
  File "bgp_config.j2", line 18, in root
  File "/usr/local/lib/python3.9/site-packages/jinja2/runtime.py", line 747, in _fail_with_undefined_error
    raise self._undefined_exception(self._undefined_message)
jinja2.exceptions.UndefinedError: 'dict object' has no attribute 'router_id'

During handling of the above exception, another exception occurred:

Traceback (most recent call last):
  File "/usr/local/lib/python3.9/site-packages/nornir/core/task.py", line 98, in start
    r = self.task(self, **self.params)
  File "/usr/local/lib/python3.9/site-packages/nornir_jinja2/plugins/tasks/template_file.py", line 43, in template_file
    text = t.render(host=task.host, **kwargs)
  File "/usr/local/lib/python3.9/site-packages/jinja2/environment.py", line 1090, in render
    self.environment.handle_exception()
  File "/usr/local/lib/python3.9/site-packages/jinja2/environment.py", line 830, in handle_exception
    from .debug import rewrite_traceback_stack
ImportError: cannot import name 'rewrite_traceback_stack' from partially initialized module 'jinja2.debug' (most likely due to a circular import) (/usr/local/lib/python3.9/site-packages/jinja2/debug.py)

2021-03-10 16:21:05,184 - nornir.core.task -    ERROR -      start() - Host 'RR-2': task 'Getting iBGP Config' failed with traceback:
Traceback (most recent call last):
  File "/usr/local/lib/python3.9/site-packages/nornir/core/task.py", line 98, in start
    r = self.task(self, **self.params)
  File "/usr/local/lib/python3.9/site-packages/nornir_jinja2/plugins/tasks/template_file.py", line 43, in template_file
    text = t.render(host=task.host, **kwargs)
  File "/usr/local/lib/python3.9/site-packages/jinja2/environment.py", line 1090, in render
    self.environment.handle_exception()
  File "/usr/local/lib/python3.9/site-packages/jinja2/environment.py", line 832, in handle_exception
    reraise(*rewrite_traceback_stack(source=source))
  File "/usr/local/lib/python3.9/site-packages/jinja2/_compat.py", line 28, in reraise
    raise value.with_traceback(tb)
  File "bgp_config.j2", line 3, in top-level template code
    {% if host.conf.bgp.route-reflector == True %}
jinja2.exceptions.UndefinedError: 'dict object' has no attribute 'route'

2021-03-10 16:21:05,185 - nornir.core.task -    ERROR -      start() - Host 'R1': task 'Getting iBGP Config' failed with traceback:
Traceback (most recent call last):
  File "/usr/local/lib/python3.9/site-packages/jinja2/environment.py", line 1088, in render
    return concat(self.root_render_func(self.new_context(vars)))
  File "bgp_config.j2", line 20, in root
  File "/usr/local/lib/python3.9/site-packages/jinja2/runtime.py", line 747, in _fail_with_undefined_error
    raise self._undefined_exception(self._undefined_message)
jinja2.exceptions.UndefinedError: 'dict object' has no attribute 'route'

During handling of the above exception, another exception occurred:

Traceback (most recent call last):
  File "/usr/local/lib/python3.9/site-packages/nornir/core/task.py", line 98, in start
    r = self.task(self, **self.params)
  File "/usr/local/lib/python3.9/site-packages/nornir_jinja2/plugins/tasks/template_file.py", line 43, in template_file
    text = t.render(host=task.host, **kwargs)
  File "/usr/local/lib/python3.9/site-packages/jinja2/environment.py", line 1090, in render
    self.environment.handle_exception()
  File "/usr/local/lib/python3.9/site-packages/jinja2/environment.py", line 830, in handle_exception
    from .debug import rewrite_traceback_stack
ImportError: cannot import name 'rewrite_traceback_stack' from partially initialized module 'jinja2.debug' (most likely due to a circular import) (/usr/local/lib/python3.9/site-packages/jinja2/debug.py)

2021-03-10 16:21:05,185 - nornir.core.task -    ERROR -      start() - Host 'R3': task 'Getting iBGP Config' failed with traceback:
Traceback (most recent call last):
  File "/usr/local/lib/python3.9/site-packages/nornir/core/task.py", line 98, in start
    r = self.task(self, **self.params)
  File "/usr/local/lib/python3.9/site-packages/nornir_jinja2/plugins/tasks/template_file.py", line 43, in template_file
    text = t.render(host=task.host, **kwargs)
  File "/usr/local/lib/python3.9/site-packages/jinja2/environment.py", line 1090, in render
    self.environment.handle_exception()
  File "/usr/local/lib/python3.9/site-packages/jinja2/environment.py", line 832, in handle_exception
    reraise(*rewrite_traceback_stack(source=source))
  File "/usr/local/lib/python3.9/site-packages/jinja2/_compat.py", line 28, in reraise
    raise value.with_traceback(tb)
  File "bgp_config.j2", line 3, in top-level template code
    {% if host.conf.bgp.route-reflector == True %}
jinja2.exceptions.UndefinedError: 'dict object' has no attribute 'route'

2021-03-10 16:21:05,185 - nornir.core.task -    ERROR -      start() - Host 'R2': task 'load_variable' failed with traceback:
Traceback (most recent call last):
  File "/usr/local/lib/python3.9/site-packages/nornir/core/task.py", line 98, in start
    r = self.task(self, **self.params)
  File "/Users/vishalgajjar/Documents/lab/bgp config/bgp_config.py", line 14, in load_variable
    bgp_configuration(task)
  File "/Users/vishalgajjar/Documents/lab/bgp config/bgp_config.py", line 18, in bgp_configuration
    bgp_j2_temp = task.run(
  File "/usr/local/lib/python3.9/site-packages/nornir/core/task.py", line 168, in run
    raise NornirSubTaskError(task=run_task, result=r)
nornir.core.exceptions.NornirSubTaskError: Subtask: Getting iBGP Config (failed)


2021-03-10 16:21:05,185 - nornir.core.task -    ERROR -      start() - Host 'R4': task 'load_variable' failed with traceback:
Traceback (most recent call last):
  File "/usr/local/lib/python3.9/site-packages/nornir/core/task.py", line 98, in start
    r = self.task(self, **self.params)
  File "/Users/vishalgajjar/Documents/lab/bgp config/bgp_config.py", line 14, in load_variable
    bgp_configuration(task)
  File "/Users/vishalgajjar/Documents/lab/bgp config/bgp_config.py", line 18, in bgp_configuration
    bgp_j2_temp = task.run(
  File "/usr/local/lib/python3.9/site-packages/nornir/core/task.py", line 168, in run
    raise NornirSubTaskError(task=run_task, result=r)
nornir.core.exceptions.NornirSubTaskError: Subtask: Getting iBGP Config (failed)


2021-03-10 16:21:05,185 - nornir.core.task -    ERROR -      start() - Host 'RR-1': task 'load_variable' failed with traceback:
Traceback (most recent call last):
  File "/usr/local/lib/python3.9/site-packages/nornir/core/task.py", line 98, in start
    r = self.task(self, **self.params)
  File "/Users/vishalgajjar/Documents/lab/bgp config/bgp_config.py", line 14, in load_variable
    bgp_configuration(task)
  File "/Users/vishalgajjar/Documents/lab/bgp config/bgp_config.py", line 18, in bgp_configuration
    bgp_j2_temp = task.run(
  File "/usr/local/lib/python3.9/site-packages/nornir/core/task.py", line 168, in run
    raise NornirSubTaskError(task=run_task, result=r)
nornir.core.exceptions.NornirSubTaskError: Subtask: Getting iBGP Config (failed)


2021-03-10 16:21:05,186 - nornir.core.task -    ERROR -      start() - Host 'RR-2': task 'load_variable' failed with traceback:
Traceback (most recent call last):
  File "/usr/local/lib/python3.9/site-packages/nornir/core/task.py", line 98, in start
    r = self.task(self, **self.params)
  File "/Users/vishalgajjar/Documents/lab/bgp config/bgp_config.py", line 14, in load_variable
    bgp_configuration(task)
  File "/Users/vishalgajjar/Documents/lab/bgp config/bgp_config.py", line 18, in bgp_configuration
    bgp_j2_temp = task.run(
  File "/usr/local/lib/python3.9/site-packages/nornir/core/task.py", line 168, in run
    raise NornirSubTaskError(task=run_task, result=r)
nornir.core.exceptions.NornirSubTaskError: Subtask: Getting iBGP Config (failed)


2021-03-10 16:21:05,186 - nornir.core.task -    ERROR -      start() - Host 'R1': task 'load_variable' failed with traceback:
Traceback (most recent call last):
  File "/usr/local/lib/python3.9/site-packages/nornir/core/task.py", line 98, in start
    r = self.task(self, **self.params)
  File "/Users/vishalgajjar/Documents/lab/bgp config/bgp_config.py", line 14, in load_variable
    bgp_configuration(task)
  File "/Users/vishalgajjar/Documents/lab/bgp config/bgp_config.py", line 18, in bgp_configuration
    bgp_j2_temp = task.run(
  File "/usr/local/lib/python3.9/site-packages/nornir/core/task.py", line 168, in run
    raise NornirSubTaskError(task=run_task, result=r)
nornir.core.exceptions.NornirSubTaskError: Subtask: Getting iBGP Config (failed)


2021-03-10 16:21:05,186 - nornir.core.task -    ERROR -      start() - Host 'R3': task 'load_variable' failed with traceback:
Traceback (most recent call last):
  File "/usr/local/lib/python3.9/site-packages/nornir/core/task.py", line 98, in start
    r = self.task(self, **self.params)
  File "/Users/vishalgajjar/Documents/lab/bgp config/bgp_config.py", line 14, in load_variable
    bgp_configuration(task)
  File "/Users/vishalgajjar/Documents/lab/bgp config/bgp_config.py", line 18, in bgp_configuration
    bgp_j2_temp = task.run(
  File "/usr/local/lib/python3.9/site-packages/nornir/core/task.py", line 168, in run
    raise NornirSubTaskError(task=run_task, result=r)
nornir.core.exceptions.NornirSubTaskError: Subtask: Getting iBGP Config (failed)


2021-03-10 16:23:12,799 -  nornir.core -     INFO -        run() - Running task 'load_variable' with args {} on 6 hosts
2021-03-10 16:23:12,865 - nornir.core.task -    ERROR -      start() - Host 'R2': task 'Getting iBGP Config' failed with traceback:
Traceback (most recent call last):
  File "/usr/local/lib/python3.9/site-packages/nornir/core/task.py", line 98, in start
    r = self.task(self, **self.params)
  File "/usr/local/lib/python3.9/site-packages/nornir_jinja2/plugins/tasks/template_file.py", line 43, in template_file
    text = t.render(host=task.host, **kwargs)
  File "/usr/local/lib/python3.9/site-packages/jinja2/environment.py", line 1090, in render
    self.environment.handle_exception()
  File "/usr/local/lib/python3.9/site-packages/jinja2/environment.py", line 832, in handle_exception
    reraise(*rewrite_traceback_stack(source=source))
  File "/usr/local/lib/python3.9/site-packages/jinja2/_compat.py", line 28, in reraise
    raise value.with_traceback(tb)
  File "bgp_config.j2", line 12, in top-level template code
    {%if host.conf.bgp.route_reflector==Falese %}
jinja2.exceptions.UndefinedError: 'Falese' is undefined

2021-03-10 16:23:12,866 - nornir.core.task -    ERROR -      start() - Host 'RR-1': task 'Getting iBGP Config' failed with traceback:
Traceback (most recent call last):
  File "/usr/local/lib/python3.9/site-packages/nornir/core/task.py", line 98, in start
    r = self.task(self, **self.params)
  File "/usr/local/lib/python3.9/site-packages/nornir_jinja2/plugins/tasks/template_file.py", line 43, in template_file
    text = t.render(host=task.host, **kwargs)
  File "/usr/local/lib/python3.9/site-packages/jinja2/environment.py", line 1090, in render
    self.environment.handle_exception()
  File "/usr/local/lib/python3.9/site-packages/jinja2/environment.py", line 832, in handle_exception
    reraise(*rewrite_traceback_stack(source=source))
  File "/usr/local/lib/python3.9/site-packages/jinja2/_compat.py", line 28, in reraise
    raise value.with_traceback(tb)
  File "bgp_config.j2", line 2, in top-level template code
    bgp router-id {{host.conf.bgp.router_id}}
jinja2.exceptions.UndefinedError: 'dict object' has no attribute 'router_id'

2021-03-10 16:23:12,866 - nornir.core.task -    ERROR -      start() - Host 'R1': task 'Getting iBGP Config' failed with traceback:
Traceback (most recent call last):
  File "/usr/local/lib/python3.9/site-packages/nornir/core/task.py", line 98, in start
    r = self.task(self, **self.params)
  File "/usr/local/lib/python3.9/site-packages/nornir_jinja2/plugins/tasks/template_file.py", line 43, in template_file
    text = t.render(host=task.host, **kwargs)
  File "/usr/local/lib/python3.9/site-packages/jinja2/environment.py", line 1090, in render
    self.environment.handle_exception()
  File "/usr/local/lib/python3.9/site-packages/jinja2/environment.py", line 832, in handle_exception
    reraise(*rewrite_traceback_stack(source=source))
  File "/usr/local/lib/python3.9/site-packages/jinja2/_compat.py", line 28, in reraise
    raise value.with_traceback(tb)
  File "bgp_config.j2", line 12, in top-level template code
    {%if host.conf.bgp.route_reflector==Falese %}
jinja2.exceptions.UndefinedError: 'Falese' is undefined

2021-03-10 16:23:12,867 - nornir.core.task -    ERROR -      start() - Host 'R1': task 'load_variable' failed with traceback:
Traceback (most recent call last):
  File "/usr/local/lib/python3.9/site-packages/nornir/core/task.py", line 98, in start
    r = self.task(self, **self.params)
  File "/Users/vishalgajjar/Documents/lab/bgp config/bgp_config.py", line 14, in load_variable
    bgp_configuration(task)
  File "/Users/vishalgajjar/Documents/lab/bgp config/bgp_config.py", line 18, in bgp_configuration
    bgp_j2_temp = task.run(
  File "/usr/local/lib/python3.9/site-packages/nornir/core/task.py", line 168, in run
    raise NornirSubTaskError(task=run_task, result=r)
nornir.core.exceptions.NornirSubTaskError: Subtask: Getting iBGP Config (failed)


2021-03-10 16:23:12,866 - nornir.core.task -    ERROR -      start() - Host 'R3': task 'Getting iBGP Config' failed with traceback:
Traceback (most recent call last):
  File "/usr/local/lib/python3.9/site-packages/jinja2/environment.py", line 1088, in render
    return concat(self.root_render_func(self.new_context(vars)))
  File "bgp_config.j2", line 41, in root
  File "/usr/local/lib/python3.9/site-packages/jinja2/runtime.py", line 747, in _fail_with_undefined_error
    raise self._undefined_exception(self._undefined_message)
jinja2.exceptions.UndefinedError: 'Falese' is undefined

During handling of the above exception, another exception occurred:

Traceback (most recent call last):
  File "/usr/local/lib/python3.9/site-packages/nornir/core/task.py", line 98, in start
    r = self.task(self, **self.params)
  File "/usr/local/lib/python3.9/site-packages/nornir_jinja2/plugins/tasks/template_file.py", line 43, in template_file
    text = t.render(host=task.host, **kwargs)
  File "/usr/local/lib/python3.9/site-packages/jinja2/environment.py", line 1090, in render
    self.environment.handle_exception()
  File "/usr/local/lib/python3.9/site-packages/jinja2/environment.py", line 830, in handle_exception
    from .debug import rewrite_traceback_stack
ImportError: cannot import name 'rewrite_traceback_stack' from partially initialized module 'jinja2.debug' (most likely due to a circular import) (/usr/local/lib/python3.9/site-packages/jinja2/debug.py)

2021-03-10 16:23:12,866 - nornir.core.task -    ERROR -      start() - Host 'RR-2': task 'Getting iBGP Config' failed with traceback:
Traceback (most recent call last):
  File "/usr/local/lib/python3.9/site-packages/nornir/core/task.py", line 98, in start
    r = self.task(self, **self.params)
  File "/usr/local/lib/python3.9/site-packages/nornir_jinja2/plugins/tasks/template_file.py", line 43, in template_file
    text = t.render(host=task.host, **kwargs)
  File "/usr/local/lib/python3.9/site-packages/jinja2/environment.py", line 1090, in render
    self.environment.handle_exception()
  File "/usr/local/lib/python3.9/site-packages/jinja2/environment.py", line 832, in handle_exception
    reraise(*rewrite_traceback_stack(source=source))
  File "/usr/local/lib/python3.9/site-packages/jinja2/_compat.py", line 28, in reraise
    raise value.with_traceback(tb)
  File "bgp_config.j2", line 12, in top-level template code
    {%if host.conf.bgp.route_reflector==Falese %}
jinja2.exceptions.UndefinedError: 'Falese' is undefined

2021-03-10 16:23:12,866 - nornir.core.task -    ERROR -      start() - Host 'R2': task 'load_variable' failed with traceback:
Traceback (most recent call last):
  File "/usr/local/lib/python3.9/site-packages/nornir/core/task.py", line 98, in start
    r = self.task(self, **self.params)
  File "/Users/vishalgajjar/Documents/lab/bgp config/bgp_config.py", line 14, in load_variable
    bgp_configuration(task)
  File "/Users/vishalgajjar/Documents/lab/bgp config/bgp_config.py", line 18, in bgp_configuration
    bgp_j2_temp = task.run(
  File "/usr/local/lib/python3.9/site-packages/nornir/core/task.py", line 168, in run
    raise NornirSubTaskError(task=run_task, result=r)
nornir.core.exceptions.NornirSubTaskError: Subtask: Getting iBGP Config (failed)


2021-03-10 16:23:12,866 - nornir.core.task -    ERROR -      start() - Host 'RR-1': task 'load_variable' failed with traceback:
Traceback (most recent call last):
  File "/usr/local/lib/python3.9/site-packages/nornir/core/task.py", line 98, in start
    r = self.task(self, **self.params)
  File "/Users/vishalgajjar/Documents/lab/bgp config/bgp_config.py", line 14, in load_variable
    bgp_configuration(task)
  File "/Users/vishalgajjar/Documents/lab/bgp config/bgp_config.py", line 18, in bgp_configuration
    bgp_j2_temp = task.run(
  File "/usr/local/lib/python3.9/site-packages/nornir/core/task.py", line 168, in run
    raise NornirSubTaskError(task=run_task, result=r)
nornir.core.exceptions.NornirSubTaskError: Subtask: Getting iBGP Config (failed)


2021-03-10 16:23:12,866 - nornir.core.task -    ERROR -      start() - Host 'R4': task 'Getting iBGP Config' failed with traceback:
Traceback (most recent call last):
  File "/usr/local/lib/python3.9/site-packages/nornir/core/task.py", line 98, in start
    r = self.task(self, **self.params)
  File "/usr/local/lib/python3.9/site-packages/nornir_jinja2/plugins/tasks/template_file.py", line 43, in template_file
    text = t.render(host=task.host, **kwargs)
  File "/usr/local/lib/python3.9/site-packages/jinja2/environment.py", line 1090, in render
    self.environment.handle_exception()
  File "/usr/local/lib/python3.9/site-packages/jinja2/environment.py", line 832, in handle_exception
    reraise(*rewrite_traceback_stack(source=source))
  File "/usr/local/lib/python3.9/site-packages/jinja2/_compat.py", line 28, in reraise
    raise value.with_traceback(tb)
  File "bgp_config.j2", line 12, in top-level template code
    {%if host.conf.bgp.route_reflector==Falese %}
jinja2.exceptions.UndefinedError: 'Falese' is undefined

2021-03-10 16:23:12,867 - nornir.core.task -    ERROR -      start() - Host 'R3': task 'load_variable' failed with traceback:
Traceback (most recent call last):
  File "/usr/local/lib/python3.9/site-packages/nornir/core/task.py", line 98, in start
    r = self.task(self, **self.params)
  File "/Users/vishalgajjar/Documents/lab/bgp config/bgp_config.py", line 14, in load_variable
    bgp_configuration(task)
  File "/Users/vishalgajjar/Documents/lab/bgp config/bgp_config.py", line 18, in bgp_configuration
    bgp_j2_temp = task.run(
  File "/usr/local/lib/python3.9/site-packages/nornir/core/task.py", line 168, in run
    raise NornirSubTaskError(task=run_task, result=r)
nornir.core.exceptions.NornirSubTaskError: Subtask: Getting iBGP Config (failed)


2021-03-10 16:23:12,867 - nornir.core.task -    ERROR -      start() - Host 'RR-2': task 'load_variable' failed with traceback:
Traceback (most recent call last):
  File "/usr/local/lib/python3.9/site-packages/nornir/core/task.py", line 98, in start
    r = self.task(self, **self.params)
  File "/Users/vishalgajjar/Documents/lab/bgp config/bgp_config.py", line 14, in load_variable
    bgp_configuration(task)
  File "/Users/vishalgajjar/Documents/lab/bgp config/bgp_config.py", line 18, in bgp_configuration
    bgp_j2_temp = task.run(
  File "/usr/local/lib/python3.9/site-packages/nornir/core/task.py", line 168, in run
    raise NornirSubTaskError(task=run_task, result=r)
nornir.core.exceptions.NornirSubTaskError: Subtask: Getting iBGP Config (failed)


2021-03-10 16:23:12,868 - nornir.core.task -    ERROR -      start() - Host 'R4': task 'load_variable' failed with traceback:
Traceback (most recent call last):
  File "/usr/local/lib/python3.9/site-packages/nornir/core/task.py", line 98, in start
    r = self.task(self, **self.params)
  File "/Users/vishalgajjar/Documents/lab/bgp config/bgp_config.py", line 14, in load_variable
    bgp_configuration(task)
  File "/Users/vishalgajjar/Documents/lab/bgp config/bgp_config.py", line 18, in bgp_configuration
    bgp_j2_temp = task.run(
  File "/usr/local/lib/python3.9/site-packages/nornir/core/task.py", line 168, in run
    raise NornirSubTaskError(task=run_task, result=r)
nornir.core.exceptions.NornirSubTaskError: Subtask: Getting iBGP Config (failed)


2021-03-10 16:23:41,385 -  nornir.core -     INFO -        run() - Running task 'load_variable' with args {} on 6 hosts
2021-03-10 16:23:41,457 - nornir.core.task -    ERROR -      start() - Host 'R2': task 'Getting iBGP Config' failed with traceback:
Traceback (most recent call last):
  File "/usr/local/lib/python3.9/site-packages/nornir/core/task.py", line 98, in start
    r = self.task(self, **self.params)
  File "/usr/local/lib/python3.9/site-packages/nornir_jinja2/plugins/tasks/template_file.py", line 43, in template_file
    text = t.render(host=task.host, **kwargs)
  File "/usr/local/lib/python3.9/site-packages/jinja2/environment.py", line 1090, in render
    self.environment.handle_exception()
  File "/usr/local/lib/python3.9/site-packages/jinja2/environment.py", line 832, in handle_exception
    reraise(*rewrite_traceback_stack(source=source))
  File "/usr/local/lib/python3.9/site-packages/jinja2/_compat.py", line 28, in reraise
    raise value.with_traceback(tb)
  File "bgp_config.j2", line 13, in top-level template code
    {% for neighbor in host.conf.bgp.neighbors%}
jinja2.exceptions.UndefinedError: 'dict object' has no attribute 'neighbors'

2021-03-10 16:23:41,457 - nornir.core.task -    ERROR -      start() - Host 'RR-1': task 'Getting iBGP Config' failed with traceback:
Traceback (most recent call last):
  File "/usr/local/lib/python3.9/site-packages/nornir/core/task.py", line 98, in start
    r = self.task(self, **self.params)
  File "/usr/local/lib/python3.9/site-packages/nornir_jinja2/plugins/tasks/template_file.py", line 43, in template_file
    text = t.render(host=task.host, **kwargs)
  File "/usr/local/lib/python3.9/site-packages/jinja2/environment.py", line 1090, in render
    self.environment.handle_exception()
  File "/usr/local/lib/python3.9/site-packages/jinja2/environment.py", line 832, in handle_exception
    reraise(*rewrite_traceback_stack(source=source))
  File "/usr/local/lib/python3.9/site-packages/jinja2/_compat.py", line 28, in reraise
    raise value.with_traceback(tb)
  File "bgp_config.j2", line 2, in top-level template code
    bgp router-id {{host.conf.bgp.router_id}}
jinja2.exceptions.UndefinedError: 'dict object' has no attribute 'router_id'

2021-03-10 16:23:41,458 - nornir.core.task -    ERROR -      start() - Host 'R3': task 'Getting iBGP Config' failed with traceback:
Traceback (most recent call last):
  File "/usr/local/lib/python3.9/site-packages/nornir/core/task.py", line 98, in start
    r = self.task(self, **self.params)
  File "/usr/local/lib/python3.9/site-packages/nornir_jinja2/plugins/tasks/template_file.py", line 43, in template_file
    text = t.render(host=task.host, **kwargs)
  File "/usr/local/lib/python3.9/site-packages/jinja2/environment.py", line 1090, in render
    self.environment.handle_exception()
  File "/usr/local/lib/python3.9/site-packages/jinja2/environment.py", line 832, in handle_exception
    reraise(*rewrite_traceback_stack(source=source))
  File "/usr/local/lib/python3.9/site-packages/jinja2/_compat.py", line 28, in reraise
    raise value.with_traceback(tb)
  File "bgp_config.j2", line 13, in top-level template code
    {% for neighbor in host.conf.bgp.neighbors%}
jinja2.exceptions.UndefinedError: 'dict object' has no attribute 'neighbors'

2021-03-10 16:23:41,458 - nornir.core.task -    ERROR -      start() - Host 'R1': task 'Getting iBGP Config' failed with traceback:
Traceback (most recent call last):
  File "/usr/local/lib/python3.9/site-packages/nornir/core/task.py", line 98, in start
    r = self.task(self, **self.params)
  File "/usr/local/lib/python3.9/site-packages/nornir_jinja2/plugins/tasks/template_file.py", line 43, in template_file
    text = t.render(host=task.host, **kwargs)
  File "/usr/local/lib/python3.9/site-packages/jinja2/environment.py", line 1090, in render
    self.environment.handle_exception()
  File "/usr/local/lib/python3.9/site-packages/jinja2/environment.py", line 832, in handle_exception
    reraise(*rewrite_traceback_stack(source=source))
  File "/usr/local/lib/python3.9/site-packages/jinja2/_compat.py", line 28, in reraise
    raise value.with_traceback(tb)
  File "bgp_config.j2", line 13, in top-level template code
    {% for neighbor in host.conf.bgp.neighbors%}
jinja2.exceptions.UndefinedError: 'dict object' has no attribute 'neighbors'

2021-03-10 16:23:41,458 - nornir.core.task -    ERROR -      start() - Host 'R4': task 'Getting iBGP Config' failed with traceback:
Traceback (most recent call last):
  File "/usr/local/lib/python3.9/site-packages/nornir/core/task.py", line 98, in start
    r = self.task(self, **self.params)
  File "/usr/local/lib/python3.9/site-packages/nornir_jinja2/plugins/tasks/template_file.py", line 43, in template_file
    text = t.render(host=task.host, **kwargs)
  File "/usr/local/lib/python3.9/site-packages/jinja2/environment.py", line 1090, in render
    self.environment.handle_exception()
  File "/usr/local/lib/python3.9/site-packages/jinja2/environment.py", line 832, in handle_exception
    reraise(*rewrite_traceback_stack(source=source))
  File "/usr/local/lib/python3.9/site-packages/jinja2/_compat.py", line 28, in reraise
    raise value.with_traceback(tb)
  File "bgp_config.j2", line 13, in top-level template code
    {% for neighbor in host.conf.bgp.neighbors%}
jinja2.exceptions.UndefinedError: 'dict object' has no attribute 'neighbors'

2021-03-10 16:23:41,458 - nornir.core.task -    ERROR -      start() - Host 'R2': task 'load_variable' failed with traceback:
Traceback (most recent call last):
  File "/usr/local/lib/python3.9/site-packages/nornir/core/task.py", line 98, in start
    r = self.task(self, **self.params)
  File "/Users/vishalgajjar/Documents/lab/bgp config/bgp_config.py", line 14, in load_variable
    bgp_configuration(task)
  File "/Users/vishalgajjar/Documents/lab/bgp config/bgp_config.py", line 18, in bgp_configuration
    bgp_j2_temp = task.run(
  File "/usr/local/lib/python3.9/site-packages/nornir/core/task.py", line 168, in run
    raise NornirSubTaskError(task=run_task, result=r)
nornir.core.exceptions.NornirSubTaskError: Subtask: Getting iBGP Config (failed)


2021-03-10 16:23:41,458 - nornir.core.task -    ERROR -      start() - Host 'RR-1': task 'load_variable' failed with traceback:
Traceback (most recent call last):
  File "/usr/local/lib/python3.9/site-packages/nornir/core/task.py", line 98, in start
    r = self.task(self, **self.params)
  File "/Users/vishalgajjar/Documents/lab/bgp config/bgp_config.py", line 14, in load_variable
    bgp_configuration(task)
  File "/Users/vishalgajjar/Documents/lab/bgp config/bgp_config.py", line 18, in bgp_configuration
    bgp_j2_temp = task.run(
  File "/usr/local/lib/python3.9/site-packages/nornir/core/task.py", line 168, in run
    raise NornirSubTaskError(task=run_task, result=r)
nornir.core.exceptions.NornirSubTaskError: Subtask: Getting iBGP Config (failed)


2021-03-10 16:23:41,459 - nornir.core.task -    ERROR -      start() - Host 'R4': task 'load_variable' failed with traceback:
Traceback (most recent call last):
  File "/usr/local/lib/python3.9/site-packages/nornir/core/task.py", line 98, in start
    r = self.task(self, **self.params)
  File "/Users/vishalgajjar/Documents/lab/bgp config/bgp_config.py", line 14, in load_variable
    bgp_configuration(task)
  File "/Users/vishalgajjar/Documents/lab/bgp config/bgp_config.py", line 18, in bgp_configuration
    bgp_j2_temp = task.run(
  File "/usr/local/lib/python3.9/site-packages/nornir/core/task.py", line 168, in run
    raise NornirSubTaskError(task=run_task, result=r)
nornir.core.exceptions.NornirSubTaskError: Subtask: Getting iBGP Config (failed)


2021-03-10 16:23:41,459 - nornir.core.task -    ERROR -      start() - Host 'R3': task 'load_variable' failed with traceback:
Traceback (most recent call last):
  File "/usr/local/lib/python3.9/site-packages/nornir/core/task.py", line 98, in start
    r = self.task(self, **self.params)
  File "/Users/vishalgajjar/Documents/lab/bgp config/bgp_config.py", line 14, in load_variable
    bgp_configuration(task)
  File "/Users/vishalgajjar/Documents/lab/bgp config/bgp_config.py", line 18, in bgp_configuration
    bgp_j2_temp = task.run(
  File "/usr/local/lib/python3.9/site-packages/nornir/core/task.py", line 168, in run
    raise NornirSubTaskError(task=run_task, result=r)
nornir.core.exceptions.NornirSubTaskError: Subtask: Getting iBGP Config (failed)


2021-03-10 16:23:41,459 - nornir.core.task -    ERROR -      start() - Host 'R1': task 'load_variable' failed with traceback:
Traceback (most recent call last):
  File "/usr/local/lib/python3.9/site-packages/nornir/core/task.py", line 98, in start
    r = self.task(self, **self.params)
  File "/Users/vishalgajjar/Documents/lab/bgp config/bgp_config.py", line 14, in load_variable
    bgp_configuration(task)
  File "/Users/vishalgajjar/Documents/lab/bgp config/bgp_config.py", line 18, in bgp_configuration
    bgp_j2_temp = task.run(
  File "/usr/local/lib/python3.9/site-packages/nornir/core/task.py", line 168, in run
    raise NornirSubTaskError(task=run_task, result=r)
nornir.core.exceptions.NornirSubTaskError: Subtask: Getting iBGP Config (failed)


2021-03-10 16:26:36,269 -  nornir.core -     INFO -        run() - Running task 'load_variable' with args {} on 6 hosts
2021-03-10 16:26:36,336 - nornir.core.task -    ERROR -      start() - Host 'R1': task 'Getting iBGP Config' failed with traceback:
Traceback (most recent call last):
  File "/usr/local/lib/python3.9/site-packages/nornir/core/task.py", line 98, in start
    r = self.task(self, **self.params)
  File "/usr/local/lib/python3.9/site-packages/nornir_jinja2/plugins/tasks/template_file.py", line 43, in template_file
    text = t.render(host=task.host, **kwargs)
  File "/usr/local/lib/python3.9/site-packages/jinja2/environment.py", line 1090, in render
    self.environment.handle_exception()
  File "/usr/local/lib/python3.9/site-packages/jinja2/environment.py", line 832, in handle_exception
    reraise(*rewrite_traceback_stack(source=source))
  File "/usr/local/lib/python3.9/site-packages/jinja2/_compat.py", line 28, in reraise
    raise value.with_traceback(tb)
  File "bgp_config.j2", line 15, in top-level template code
    neighbor {{neighbor}} update-source {{host.conf.bgp.update_source}}
jinja2.exceptions.UndefinedError: 'dict object' has no attribute 'update_source'

2021-03-10 16:26:36,337 - nornir.core.task -    ERROR -      start() - Host 'R1': task 'load_variable' failed with traceback:
Traceback (most recent call last):
  File "/usr/local/lib/python3.9/site-packages/nornir/core/task.py", line 98, in start
    r = self.task(self, **self.params)
  File "/Users/vishalgajjar/Documents/lab/bgp config/bgp_config.py", line 14, in load_variable
    bgp_configuration(task)
  File "/Users/vishalgajjar/Documents/lab/bgp config/bgp_config.py", line 18, in bgp_configuration
    bgp_j2_temp = task.run(
  File "/usr/local/lib/python3.9/site-packages/nornir/core/task.py", line 168, in run
    raise NornirSubTaskError(task=run_task, result=r)
nornir.core.exceptions.NornirSubTaskError: Subtask: Getting iBGP Config (failed)


2021-03-10 16:27:15,689 -  nornir.core -     INFO -        run() - Running task 'load_variable' with args {} on 6 hosts
2021-03-13 08:26:52,382 -  nornir.core -     INFO -        run() - Running task 'load_variable' with args {} on 1 hosts
2021-03-13 08:26:52,410 - nornir.core.task -    ERROR -      start() - Host 'RR-1': task 'Getting iBGP Config' failed with traceback:
Traceback (most recent call last):
  File "/usr/local/lib/python3.9/site-packages/nornir/core/task.py", line 98, in start
    r = self.task(self, **self.params)
  File "/usr/local/lib/python3.9/site-packages/nornir_jinja2/plugins/tasks/template_file.py", line 43, in template_file
    text = t.render(host=task.host, **kwargs)
  File "/usr/local/lib/python3.9/site-packages/jinja2/environment.py", line 1090, in render
    self.environment.handle_exception()
  File "/usr/local/lib/python3.9/site-packages/jinja2/environment.py", line 832, in handle_exception
    reraise(*rewrite_traceback_stack(source=source))
  File "/usr/local/lib/python3.9/site-packages/jinja2/_compat.py", line 28, in reraise
    raise value.with_traceback(tb)
  File "bgp_config.j2", line 1, in top-level template code
    hostname {{ host.conf.hostname }}
jinja2.exceptions.UndefinedError: 'dict object' has no attribute 'hostname'

2021-03-13 08:26:52,411 - nornir.core.task -    ERROR -      start() - Host 'RR-1': task 'load_variable' failed with traceback:
Traceback (most recent call last):
  File "/usr/local/lib/python3.9/site-packages/nornir/core/task.py", line 98, in start
    r = self.task(self, **self.params)
  File "/Users/vishalgajjar/Documents/lab/bgp config/bgp_config.py", line 14, in load_variable
    bgp_configuration(task)
  File "/Users/vishalgajjar/Documents/lab/bgp config/bgp_config.py", line 18, in bgp_configuration
    bgp_j2_temp = task.run(
  File "/usr/local/lib/python3.9/site-packages/nornir/core/task.py", line 168, in run
    raise NornirSubTaskError(task=run_task, result=r)
nornir.core.exceptions.NornirSubTaskError: Subtask: Getting iBGP Config (failed)


2021-03-13 08:29:18,831 -  nornir.core -     INFO -        run() - Running task 'load_variable' with args {} on 1 hosts
2021-03-13 08:29:18,881 - nornir.core.task -    ERROR -      start() - Host 'R1': task 'Getting iBGP Config' failed with traceback:
Traceback (most recent call last):
  File "/usr/local/lib/python3.9/site-packages/nornir/core/task.py", line 98, in start
    r = self.task(self, **self.params)
  File "/usr/local/lib/python3.9/site-packages/nornir_jinja2/plugins/tasks/template_file.py", line 43, in template_file
    text = t.render(host=task.host, **kwargs)
  File "/usr/local/lib/python3.9/site-packages/jinja2/environment.py", line 1090, in render
    self.environment.handle_exception()
  File "/usr/local/lib/python3.9/site-packages/jinja2/environment.py", line 832, in handle_exception
    reraise(*rewrite_traceback_stack(source=source))
  File "/usr/local/lib/python3.9/site-packages/jinja2/_compat.py", line 28, in reraise
    raise value.with_traceback(tb)
  File "bgp_config.j2", line 13, in top-level template code
    network {{ host.conf.ip}} {{ host.conf.wildcard }} area {{ host.conf.area }}
jinja2.exceptions.UndefinedError: 'dict object' has no attribute 'ip'

2021-03-13 08:29:18,882 - nornir.core.task -    ERROR -      start() - Host 'R1': task 'load_variable' failed with traceback:
Traceback (most recent call last):
  File "/usr/local/lib/python3.9/site-packages/nornir/core/task.py", line 98, in start
    r = self.task(self, **self.params)
  File "/Users/vishalgajjar/Documents/lab/bgp config/bgp_config.py", line 14, in load_variable
    bgp_configuration(task)
  File "/Users/vishalgajjar/Documents/lab/bgp config/bgp_config.py", line 18, in bgp_configuration
    bgp_j2_temp = task.run(
  File "/usr/local/lib/python3.9/site-packages/nornir/core/task.py", line 168, in run
    raise NornirSubTaskError(task=run_task, result=r)
nornir.core.exceptions.NornirSubTaskError: Subtask: Getting iBGP Config (failed)


2021-03-13 08:41:21,759 -  nornir.core -     INFO -        run() - Running task 'load_variable' with args {} on 1 hosts
2021-03-13 08:41:21,789 - nornir.core.task -    ERROR -      start() - Host 'R1': task 'Getting iBGP Config' failed with traceback:
Traceback (most recent call last):
  File "/usr/local/lib/python3.9/site-packages/nornir/core/task.py", line 98, in start
    r = self.task(self, **self.params)
  File "/usr/local/lib/python3.9/site-packages/nornir_jinja2/plugins/tasks/template_file.py", line 43, in template_file
    text = t.render(host=task.host, **kwargs)
  File "/usr/local/lib/python3.9/site-packages/jinja2/environment.py", line 1090, in render
    self.environment.handle_exception()
  File "/usr/local/lib/python3.9/site-packages/jinja2/environment.py", line 832, in handle_exception
    reraise(*rewrite_traceback_stack(source=source))
  File "/usr/local/lib/python3.9/site-packages/jinja2/_compat.py", line 28, in reraise
    raise value.with_traceback(tb)
  File "bgp_config.j2", line 13, in top-level template code
    network {{ host.conf.n.ip}} {{ host.conf.n.wildcard }} area {{ host.conf.n.area }}
  File "/usr/local/lib/python3.9/site-packages/jinja2/environment.py", line 471, in getattr
    return getattr(obj, attribute)
jinja2.exceptions.UndefinedError: 'dict object' has no attribute 'n'

2021-03-13 08:41:21,789 - nornir.core.task -    ERROR -      start() - Host 'R1': task 'load_variable' failed with traceback:
Traceback (most recent call last):
  File "/usr/local/lib/python3.9/site-packages/nornir/core/task.py", line 98, in start
    r = self.task(self, **self.params)
  File "/Users/vishalgajjar/Documents/lab/bgp config/bgp_config.py", line 14, in load_variable
    bgp_configuration(task)
  File "/Users/vishalgajjar/Documents/lab/bgp config/bgp_config.py", line 18, in bgp_configuration
    bgp_j2_temp = task.run(
  File "/usr/local/lib/python3.9/site-packages/nornir/core/task.py", line 168, in run
    raise NornirSubTaskError(task=run_task, result=r)
nornir.core.exceptions.NornirSubTaskError: Subtask: Getting iBGP Config (failed)


2021-03-13 08:42:55,293 -  nornir.core -     INFO -        run() - Running task 'load_variable' with args {} on 1 hosts
2021-03-13 08:49:58,230 -  nornir.core -     INFO -        run() - Running task 'load_variable' with args {} on 1 hosts
2021-03-13 10:33:24,102 -  nornir.core -     INFO -        run() - Running task 'load_variable' with args {} on 2 hosts
2021-03-13 10:33:24,177 - nornir.core.task -    ERROR -      start() - Host 'R2': task 'Getting iBGP Config' failed with traceback:
Traceback (most recent call last):
  File "/usr/local/lib/python3.9/site-packages/nornir/core/task.py", line 98, in start
    r = self.task(self, **self.params)
  File "/usr/local/lib/python3.9/site-packages/nornir_jinja2/plugins/tasks/template_file.py", line 43, in template_file
    text = t.render(host=task.host, **kwargs)
  File "/usr/local/lib/python3.9/site-packages/jinja2/environment.py", line 1090, in render
    self.environment.handle_exception()
  File "/usr/local/lib/python3.9/site-packages/jinja2/environment.py", line 832, in handle_exception
    reraise(*rewrite_traceback_stack(source=source))
  File "/usr/local/lib/python3.9/site-packages/jinja2/_compat.py", line 28, in reraise
    raise value.with_traceback(tb)
  File "bgp_config.j2", line 3, in top-level template code
    {% for interface in host.conf.interfaces %}
jinja2.exceptions.UndefinedError: 'dict object' has no attribute 'interfaces'

2021-03-13 10:33:24,178 - nornir.core.task -    ERROR -      start() - Host 'R2': task 'load_variable' failed with traceback:
Traceback (most recent call last):
  File "/usr/local/lib/python3.9/site-packages/nornir/core/task.py", line 98, in start
    r = self.task(self, **self.params)
  File "/Users/vishalgajjar/Documents/lab/bgp config/bgp_config.py", line 14, in load_variable
    bgp_configuration(task)
  File "/Users/vishalgajjar/Documents/lab/bgp config/bgp_config.py", line 18, in bgp_configuration
    bgp_j2_temp = task.run(
  File "/usr/local/lib/python3.9/site-packages/nornir/core/task.py", line 168, in run
    raise NornirSubTaskError(task=run_task, result=r)
nornir.core.exceptions.NornirSubTaskError: Subtask: Getting iBGP Config (failed)


2021-03-13 10:37:39,082 -  nornir.core -     INFO -        run() - Running task 'load_variable' with args {} on 2 hosts
2021-03-13 11:25:56,872 -  nornir.core -     INFO -        run() - Running task 'load_variable' with args {} on 6 hosts
2021-03-13 11:25:56,950 - nornir.core.task -    ERROR -      start() - Host 'R3': task 'Getting iBGP Config' failed with traceback:
Traceback (most recent call last):
  File "/usr/local/lib/python3.9/site-packages/nornir/core/task.py", line 98, in start
    r = self.task(self, **self.params)
  File "/usr/local/lib/python3.9/site-packages/nornir_jinja2/plugins/tasks/template_file.py", line 42, in template_file
    t = env.get_template(template)
  File "/usr/local/lib/python3.9/site-packages/jinja2/environment.py", line 883, in get_template
    return self._load_template(name, self.make_globals(globals))
  File "/usr/local/lib/python3.9/site-packages/jinja2/environment.py", line 857, in _load_template
    template = self.loader.load(self, name, globals)
  File "/usr/local/lib/python3.9/site-packages/jinja2/loaders.py", line 115, in load
    source, filename, uptodate = self.get_source(environment, name)
  File "/usr/local/lib/python3.9/site-packages/jinja2/loaders.py", line 197, in get_source
    raise TemplateNotFound(template)
jinja2.exceptions.TemplateNotFound: int_ospf_bgp_config

2021-03-13 11:25:56,950 - nornir.core.task -    ERROR -      start() - Host 'R2': task 'Getting iBGP Config' failed with traceback:
Traceback (most recent call last):
  File "/usr/local/lib/python3.9/site-packages/nornir/core/task.py", line 98, in start
    r = self.task(self, **self.params)
  File "/usr/local/lib/python3.9/site-packages/nornir_jinja2/plugins/tasks/template_file.py", line 42, in template_file
    t = env.get_template(template)
  File "/usr/local/lib/python3.9/site-packages/jinja2/environment.py", line 883, in get_template
    return self._load_template(name, self.make_globals(globals))
  File "/usr/local/lib/python3.9/site-packages/jinja2/environment.py", line 857, in _load_template
    template = self.loader.load(self, name, globals)
  File "/usr/local/lib/python3.9/site-packages/jinja2/loaders.py", line 115, in load
    source, filename, uptodate = self.get_source(environment, name)
  File "/usr/local/lib/python3.9/site-packages/jinja2/loaders.py", line 197, in get_source
    raise TemplateNotFound(template)
jinja2.exceptions.TemplateNotFound: int_ospf_bgp_config

2021-03-13 11:25:56,950 - nornir.core.task -    ERROR -      start() - Host 'R1': task 'Getting iBGP Config' failed with traceback:
Traceback (most recent call last):
  File "/usr/local/lib/python3.9/site-packages/nornir/core/task.py", line 98, in start
    r = self.task(self, **self.params)
  File "/usr/local/lib/python3.9/site-packages/nornir_jinja2/plugins/tasks/template_file.py", line 42, in template_file
    t = env.get_template(template)
  File "/usr/local/lib/python3.9/site-packages/jinja2/environment.py", line 883, in get_template
    return self._load_template(name, self.make_globals(globals))
  File "/usr/local/lib/python3.9/site-packages/jinja2/environment.py", line 857, in _load_template
    template = self.loader.load(self, name, globals)
  File "/usr/local/lib/python3.9/site-packages/jinja2/loaders.py", line 115, in load
    source, filename, uptodate = self.get_source(environment, name)
  File "/usr/local/lib/python3.9/site-packages/jinja2/loaders.py", line 197, in get_source
    raise TemplateNotFound(template)
jinja2.exceptions.TemplateNotFound: int_ospf_bgp_config

2021-03-13 11:25:56,950 - nornir.core.task -    ERROR -      start() - Host 'RR-1': task 'Getting iBGP Config' failed with traceback:
Traceback (most recent call last):
  File "/usr/local/lib/python3.9/site-packages/nornir/core/task.py", line 98, in start
    r = self.task(self, **self.params)
  File "/usr/local/lib/python3.9/site-packages/nornir_jinja2/plugins/tasks/template_file.py", line 42, in template_file
    t = env.get_template(template)
  File "/usr/local/lib/python3.9/site-packages/jinja2/environment.py", line 883, in get_template
    return self._load_template(name, self.make_globals(globals))
  File "/usr/local/lib/python3.9/site-packages/jinja2/environment.py", line 857, in _load_template
    template = self.loader.load(self, name, globals)
  File "/usr/local/lib/python3.9/site-packages/jinja2/loaders.py", line 115, in load
    source, filename, uptodate = self.get_source(environment, name)
  File "/usr/local/lib/python3.9/site-packages/jinja2/loaders.py", line 197, in get_source
    raise TemplateNotFound(template)
jinja2.exceptions.TemplateNotFound: int_ospf_bgp_config

2021-03-13 11:25:56,950 - nornir.core.task -    ERROR -      start() - Host 'RR-2': task 'Getting iBGP Config' failed with traceback:
Traceback (most recent call last):
  File "/usr/local/lib/python3.9/site-packages/nornir/core/task.py", line 98, in start
    r = self.task(self, **self.params)
  File "/usr/local/lib/python3.9/site-packages/nornir_jinja2/plugins/tasks/template_file.py", line 42, in template_file
    t = env.get_template(template)
  File "/usr/local/lib/python3.9/site-packages/jinja2/environment.py", line 883, in get_template
    return self._load_template(name, self.make_globals(globals))
  File "/usr/local/lib/python3.9/site-packages/jinja2/environment.py", line 857, in _load_template
    template = self.loader.load(self, name, globals)
  File "/usr/local/lib/python3.9/site-packages/jinja2/loaders.py", line 115, in load
    source, filename, uptodate = self.get_source(environment, name)
  File "/usr/local/lib/python3.9/site-packages/jinja2/loaders.py", line 197, in get_source
    raise TemplateNotFound(template)
jinja2.exceptions.TemplateNotFound: int_ospf_bgp_config

2021-03-13 11:25:56,951 - nornir.core.task -    ERROR -      start() - Host 'R4': task 'Getting iBGP Config' failed with traceback:
Traceback (most recent call last):
  File "/usr/local/lib/python3.9/site-packages/nornir/core/task.py", line 98, in start
    r = self.task(self, **self.params)
  File "/usr/local/lib/python3.9/site-packages/nornir_jinja2/plugins/tasks/template_file.py", line 42, in template_file
    t = env.get_template(template)
  File "/usr/local/lib/python3.9/site-packages/jinja2/environment.py", line 883, in get_template
    return self._load_template(name, self.make_globals(globals))
  File "/usr/local/lib/python3.9/site-packages/jinja2/environment.py", line 857, in _load_template
    template = self.loader.load(self, name, globals)
  File "/usr/local/lib/python3.9/site-packages/jinja2/loaders.py", line 115, in load
    source, filename, uptodate = self.get_source(environment, name)
  File "/usr/local/lib/python3.9/site-packages/jinja2/loaders.py", line 197, in get_source
    raise TemplateNotFound(template)
jinja2.exceptions.TemplateNotFound: int_ospf_bgp_config

2021-03-13 11:25:56,951 - nornir.core.task -    ERROR -      start() - Host 'R3': task 'load_variable' failed with traceback:
Traceback (most recent call last):
  File "/usr/local/lib/python3.9/site-packages/nornir/core/task.py", line 98, in start
    r = self.task(self, **self.params)
  File "/Users/vishalgajjar/Documents/lab/bgp config/int_ospf_bgp_config.py", line 14, in load_variable
    bgp_configuration(task)
  File "/Users/vishalgajjar/Documents/lab/bgp config/int_ospf_bgp_config.py", line 18, in bgp_configuration
    bgp_j2_temp = task.run(
  File "/usr/local/lib/python3.9/site-packages/nornir/core/task.py", line 168, in run
    raise NornirSubTaskError(task=run_task, result=r)
nornir.core.exceptions.NornirSubTaskError: Subtask: Getting iBGP Config (failed)


2021-03-13 11:25:56,951 - nornir.core.task -    ERROR -      start() - Host 'RR-1': task 'load_variable' failed with traceback:
Traceback (most recent call last):
  File "/usr/local/lib/python3.9/site-packages/nornir/core/task.py", line 98, in start
    r = self.task(self, **self.params)
  File "/Users/vishalgajjar/Documents/lab/bgp config/int_ospf_bgp_config.py", line 14, in load_variable
    bgp_configuration(task)
  File "/Users/vishalgajjar/Documents/lab/bgp config/int_ospf_bgp_config.py", line 18, in bgp_configuration
    bgp_j2_temp = task.run(
  File "/usr/local/lib/python3.9/site-packages/nornir/core/task.py", line 168, in run
    raise NornirSubTaskError(task=run_task, result=r)
nornir.core.exceptions.NornirSubTaskError: Subtask: Getting iBGP Config (failed)


2021-03-13 11:25:56,952 - nornir.core.task -    ERROR -      start() - Host 'R1': task 'load_variable' failed with traceback:
Traceback (most recent call last):
  File "/usr/local/lib/python3.9/site-packages/nornir/core/task.py", line 98, in start
    r = self.task(self, **self.params)
  File "/Users/vishalgajjar/Documents/lab/bgp config/int_ospf_bgp_config.py", line 14, in load_variable
    bgp_configuration(task)
  File "/Users/vishalgajjar/Documents/lab/bgp config/int_ospf_bgp_config.py", line 18, in bgp_configuration
    bgp_j2_temp = task.run(
  File "/usr/local/lib/python3.9/site-packages/nornir/core/task.py", line 168, in run
    raise NornirSubTaskError(task=run_task, result=r)
nornir.core.exceptions.NornirSubTaskError: Subtask: Getting iBGP Config (failed)


2021-03-13 11:25:56,952 - nornir.core.task -    ERROR -      start() - Host 'R4': task 'load_variable' failed with traceback:
Traceback (most recent call last):
  File "/usr/local/lib/python3.9/site-packages/nornir/core/task.py", line 98, in start
    r = self.task(self, **self.params)
  File "/Users/vishalgajjar/Documents/lab/bgp config/int_ospf_bgp_config.py", line 14, in load_variable
    bgp_configuration(task)
  File "/Users/vishalgajjar/Documents/lab/bgp config/int_ospf_bgp_config.py", line 18, in bgp_configuration
    bgp_j2_temp = task.run(
  File "/usr/local/lib/python3.9/site-packages/nornir/core/task.py", line 168, in run
    raise NornirSubTaskError(task=run_task, result=r)
nornir.core.exceptions.NornirSubTaskError: Subtask: Getting iBGP Config (failed)


2021-03-13 11:25:56,952 - nornir.core.task -    ERROR -      start() - Host 'RR-2': task 'load_variable' failed with traceback:
Traceback (most recent call last):
  File "/usr/local/lib/python3.9/site-packages/nornir/core/task.py", line 98, in start
    r = self.task(self, **self.params)
  File "/Users/vishalgajjar/Documents/lab/bgp config/int_ospf_bgp_config.py", line 14, in load_variable
    bgp_configuration(task)
  File "/Users/vishalgajjar/Documents/lab/bgp config/int_ospf_bgp_config.py", line 18, in bgp_configuration
    bgp_j2_temp = task.run(
  File "/usr/local/lib/python3.9/site-packages/nornir/core/task.py", line 168, in run
    raise NornirSubTaskError(task=run_task, result=r)
nornir.core.exceptions.NornirSubTaskError: Subtask: Getting iBGP Config (failed)


2021-03-13 11:25:56,952 - nornir.core.task -    ERROR -      start() - Host 'R2': task 'load_variable' failed with traceback:
Traceback (most recent call last):
  File "/usr/local/lib/python3.9/site-packages/nornir/core/task.py", line 98, in start
    r = self.task(self, **self.params)
  File "/Users/vishalgajjar/Documents/lab/bgp config/int_ospf_bgp_config.py", line 14, in load_variable
    bgp_configuration(task)
  File "/Users/vishalgajjar/Documents/lab/bgp config/int_ospf_bgp_config.py", line 18, in bgp_configuration
    bgp_j2_temp = task.run(
  File "/usr/local/lib/python3.9/site-packages/nornir/core/task.py", line 168, in run
    raise NornirSubTaskError(task=run_task, result=r)
nornir.core.exceptions.NornirSubTaskError: Subtask: Getting iBGP Config (failed)


2021-03-13 11:26:33,496 -  nornir.core -     INFO -        run() - Running task 'load_variable' with args {} on 6 hosts
2021-03-13 11:26:38,626 - nornir.core.task -    ERROR -      start() - Host 'RR-2': task 'Configuring iBGP' failed with traceback:
Traceback (most recent call last):
  File "/usr/local/lib/python3.9/site-packages/netmiko/base_connection.py", line 920, in establish_connection
    self.remote_conn_pre.connect(**ssh_connect_params)
  File "/usr/local/lib/python3.9/site-packages/paramiko/client.py", line 349, in connect
    retry_on_signal(lambda: sock.connect(addr))
  File "/usr/local/lib/python3.9/site-packages/paramiko/util.py", line 283, in retry_on_signal
    return function()
  File "/usr/local/lib/python3.9/site-packages/paramiko/client.py", line 349, in <lambda>
    retry_on_signal(lambda: sock.connect(addr))
socket.timeout: timed out

During handling of the above exception, another exception occurred:

Traceback (most recent call last):
  File "/usr/local/lib/python3.9/site-packages/nornir/core/task.py", line 98, in start
    r = self.task(self, **self.params)
  File "/usr/local/lib/python3.9/site-packages/nornir_netmiko/tasks/netmiko_send_config.py", line 24, in netmiko_send_config
    net_connect = task.host.get_connection(CONNECTION_NAME, task.nornir.config)
  File "/usr/local/lib/python3.9/site-packages/nornir/core/inventory.py", line 440, in get_connection
    self.open_connection(
  File "/usr/local/lib/python3.9/site-packages/nornir/core/inventory.py", line 492, in open_connection
    conn_obj.open(
  File "/usr/local/lib/python3.9/site-packages/nornir_netmiko/connections/netmiko.py", line 59, in open
    connection = ConnectHandler(**parameters)
  File "/usr/local/lib/python3.9/site-packages/netmiko/ssh_dispatcher.py", line 312, in ConnectHandler
    return ConnectionClass(*args, **kwargs)
  File "/usr/local/lib/python3.9/site-packages/netmiko/cisco/cisco_ios.py", line 17, in __init__
    return super().__init__(*args, **kwargs)
  File "/usr/local/lib/python3.9/site-packages/netmiko/base_connection.py", line 346, in __init__
    self._open()
  File "/usr/local/lib/python3.9/site-packages/netmiko/base_connection.py", line 351, in _open
    self.establish_connection()
  File "/usr/local/lib/python3.9/site-packages/netmiko/base_connection.py", line 942, in establish_connection
    raise NetmikoTimeoutException(msg)
netmiko.ssh_exception.NetmikoTimeoutException: TCP connection to device failed.

Common causes of this problem are:
1. Incorrect hostname or IP address.
2. Wrong TCP port.
3. Intermediate firewall blocking access.

Device settings: cisco_ios 10.0.0.232:22



2021-03-13 11:26:38,627 - nornir.core.task -    ERROR -      start() - Host 'RR-2': task 'load_variable' failed with traceback:
Traceback (most recent call last):
  File "/usr/local/lib/python3.9/site-packages/nornir/core/task.py", line 98, in start
    r = self.task(self, **self.params)
  File "/Users/vishalgajjar/Documents/lab/bgp config/int_ospf_bgp_config.py", line 14, in load_variable
    bgp_configuration(task)
  File "/Users/vishalgajjar/Documents/lab/bgp config/int_ospf_bgp_config.py", line 22, in bgp_configuration
    task.run(task=netmiko_send_config,
  File "/usr/local/lib/python3.9/site-packages/nornir/core/task.py", line 168, in run
    raise NornirSubTaskError(task=run_task, result=r)
nornir.core.exceptions.NornirSubTaskError: Subtask: Configuring iBGP (failed)


2021-03-13 11:28:07,850 -  nornir.core -     INFO -        run() - Running task 'load_variable' with args {} on 6 hosts
2021-03-14 15:46:15,622 -  nornir.core -     INFO -        run() - Running task 'load_variable' with args {} on 6 hosts
2021-03-14 15:46:28,926 - nornir.core.task -    ERROR -      start() - Host 'R3': task 'netmiko_send_command' failed with traceback:
Traceback (most recent call last):
  File "/usr/local/lib/python3.9/site-packages/nornir/core/task.py", line 98, in start
    r = self.task(self, **self.params)
  File "/usr/local/lib/python3.9/site-packages/nornir_netmiko/tasks/netmiko_send_command.py", line 32, in netmiko_send_command
    result = net_connect.send_command(command_string, **kwargs)
  File "/usr/local/lib/python3.9/site-packages/netmiko/utilities.py", line 429, in wrapper_decorator
    return func(self, *args, **kwargs)
  File "/usr/local/lib/python3.9/site-packages/netmiko/base_connection.py", line 1473, in send_command
    command_string = self.normalize_cmd(command_string)
  File "/usr/local/lib/python3.9/site-packages/netmiko/base_connection.py", line 1632, in normalize_cmd
    command = command.rstrip()
AttributeError: 'list' object has no attribute 'rstrip'

2021-03-14 15:46:28,927 - nornir.core.task -    ERROR -      start() - Host 'R3': task 'load_variable' failed with traceback:
Traceback (most recent call last):
  File "/usr/local/lib/python3.9/site-packages/nornir/core/task.py", line 98, in start
    r = self.task(self, **self.params)
  File "/Users/vishalgajjar/Documents/lab/bgp config/int_ospf_bgp_config.py", line 16, in load_variable
    int_ospf_bgp_configuration(task)
  File "/Users/vishalgajjar/Documents/lab/bgp config/int_ospf_bgp_config.py", line 28, in int_ospf_bgp_configuration
    show_status_ospf_bgp(task)
  File "/Users/vishalgajjar/Documents/lab/bgp config/int_ospf_bgp_config.py", line 34, in show_status_ospf_bgp
    task.run(task=netmiko_send_command, command_string=[
  File "/usr/local/lib/python3.9/site-packages/nornir/core/task.py", line 168, in run
    raise NornirSubTaskError(task=run_task, result=r)
nornir.core.exceptions.NornirSubTaskError: Subtask: netmiko_send_command (failed)


2021-03-14 15:46:30,221 - nornir.core.task -    ERROR -      start() - Host 'R1': task 'netmiko_send_command' failed with traceback:
Traceback (most recent call last):
  File "/usr/local/lib/python3.9/site-packages/nornir/core/task.py", line 98, in start
    r = self.task(self, **self.params)
  File "/usr/local/lib/python3.9/site-packages/nornir_netmiko/tasks/netmiko_send_command.py", line 32, in netmiko_send_command
    result = net_connect.send_command(command_string, **kwargs)
  File "/usr/local/lib/python3.9/site-packages/netmiko/utilities.py", line 429, in wrapper_decorator
    return func(self, *args, **kwargs)
  File "/usr/local/lib/python3.9/site-packages/netmiko/base_connection.py", line 1473, in send_command
    command_string = self.normalize_cmd(command_string)
  File "/usr/local/lib/python3.9/site-packages/netmiko/base_connection.py", line 1632, in normalize_cmd
    command = command.rstrip()
AttributeError: 'list' object has no attribute 'rstrip'

2021-03-14 15:46:30,222 - nornir.core.task -    ERROR -      start() - Host 'R1': task 'load_variable' failed with traceback:
Traceback (most recent call last):
  File "/usr/local/lib/python3.9/site-packages/nornir/core/task.py", line 98, in start
    r = self.task(self, **self.params)
  File "/Users/vishalgajjar/Documents/lab/bgp config/int_ospf_bgp_config.py", line 16, in load_variable
    int_ospf_bgp_configuration(task)
  File "/Users/vishalgajjar/Documents/lab/bgp config/int_ospf_bgp_config.py", line 28, in int_ospf_bgp_configuration
    show_status_ospf_bgp(task)
  File "/Users/vishalgajjar/Documents/lab/bgp config/int_ospf_bgp_config.py", line 34, in show_status_ospf_bgp
    task.run(task=netmiko_send_command, command_string=[
  File "/usr/local/lib/python3.9/site-packages/nornir/core/task.py", line 168, in run
    raise NornirSubTaskError(task=run_task, result=r)
nornir.core.exceptions.NornirSubTaskError: Subtask: netmiko_send_command (failed)


2021-03-14 15:46:30,232 - nornir.core.task -    ERROR -      start() - Host 'R2': task 'netmiko_send_command' failed with traceback:
Traceback (most recent call last):
  File "/usr/local/lib/python3.9/site-packages/nornir/core/task.py", line 98, in start
    r = self.task(self, **self.params)
  File "/usr/local/lib/python3.9/site-packages/nornir_netmiko/tasks/netmiko_send_command.py", line 32, in netmiko_send_command
    result = net_connect.send_command(command_string, **kwargs)
  File "/usr/local/lib/python3.9/site-packages/netmiko/utilities.py", line 429, in wrapper_decorator
    return func(self, *args, **kwargs)
  File "/usr/local/lib/python3.9/site-packages/netmiko/base_connection.py", line 1473, in send_command
    command_string = self.normalize_cmd(command_string)
  File "/usr/local/lib/python3.9/site-packages/netmiko/base_connection.py", line 1632, in normalize_cmd
    command = command.rstrip()
AttributeError: 'list' object has no attribute 'rstrip'

2021-03-14 15:46:30,233 - nornir.core.task -    ERROR -      start() - Host 'R2': task 'load_variable' failed with traceback:
Traceback (most recent call last):
  File "/usr/local/lib/python3.9/site-packages/nornir/core/task.py", line 98, in start
    r = self.task(self, **self.params)
  File "/Users/vishalgajjar/Documents/lab/bgp config/int_ospf_bgp_config.py", line 16, in load_variable
    int_ospf_bgp_configuration(task)
  File "/Users/vishalgajjar/Documents/lab/bgp config/int_ospf_bgp_config.py", line 28, in int_ospf_bgp_configuration
    show_status_ospf_bgp(task)
  File "/Users/vishalgajjar/Documents/lab/bgp config/int_ospf_bgp_config.py", line 34, in show_status_ospf_bgp
    task.run(task=netmiko_send_command, command_string=[
  File "/usr/local/lib/python3.9/site-packages/nornir/core/task.py", line 168, in run
    raise NornirSubTaskError(task=run_task, result=r)
nornir.core.exceptions.NornirSubTaskError: Subtask: netmiko_send_command (failed)


2021-03-14 15:46:30,421 - nornir.core.task -    ERROR -      start() - Host 'R4': task 'netmiko_send_command' failed with traceback:
Traceback (most recent call last):
  File "/usr/local/lib/python3.9/site-packages/nornir/core/task.py", line 98, in start
    r = self.task(self, **self.params)
  File "/usr/local/lib/python3.9/site-packages/nornir_netmiko/tasks/netmiko_send_command.py", line 32, in netmiko_send_command
    result = net_connect.send_command(command_string, **kwargs)
  File "/usr/local/lib/python3.9/site-packages/netmiko/utilities.py", line 429, in wrapper_decorator
    return func(self, *args, **kwargs)
  File "/usr/local/lib/python3.9/site-packages/netmiko/base_connection.py", line 1473, in send_command
    command_string = self.normalize_cmd(command_string)
  File "/usr/local/lib/python3.9/site-packages/netmiko/base_connection.py", line 1632, in normalize_cmd
    command = command.rstrip()
AttributeError: 'list' object has no attribute 'rstrip'

2021-03-14 15:46:30,421 - nornir.core.task -    ERROR -      start() - Host 'R4': task 'load_variable' failed with traceback:
Traceback (most recent call last):
  File "/usr/local/lib/python3.9/site-packages/nornir/core/task.py", line 98, in start
    r = self.task(self, **self.params)
  File "/Users/vishalgajjar/Documents/lab/bgp config/int_ospf_bgp_config.py", line 16, in load_variable
    int_ospf_bgp_configuration(task)
  File "/Users/vishalgajjar/Documents/lab/bgp config/int_ospf_bgp_config.py", line 28, in int_ospf_bgp_configuration
    show_status_ospf_bgp(task)
  File "/Users/vishalgajjar/Documents/lab/bgp config/int_ospf_bgp_config.py", line 34, in show_status_ospf_bgp
    task.run(task=netmiko_send_command, command_string=[
  File "/usr/local/lib/python3.9/site-packages/nornir/core/task.py", line 168, in run
    raise NornirSubTaskError(task=run_task, result=r)
nornir.core.exceptions.NornirSubTaskError: Subtask: netmiko_send_command (failed)


2021-03-14 15:46:33,231 - nornir.core.task -    ERROR -      start() - Host 'RR-1': task 'netmiko_send_command' failed with traceback:
Traceback (most recent call last):
  File "/usr/local/lib/python3.9/site-packages/nornir/core/task.py", line 98, in start
    r = self.task(self, **self.params)
  File "/usr/local/lib/python3.9/site-packages/nornir_netmiko/tasks/netmiko_send_command.py", line 32, in netmiko_send_command
    result = net_connect.send_command(command_string, **kwargs)
  File "/usr/local/lib/python3.9/site-packages/netmiko/utilities.py", line 429, in wrapper_decorator
    return func(self, *args, **kwargs)
  File "/usr/local/lib/python3.9/site-packages/netmiko/base_connection.py", line 1473, in send_command
    command_string = self.normalize_cmd(command_string)
  File "/usr/local/lib/python3.9/site-packages/netmiko/base_connection.py", line 1632, in normalize_cmd
    command = command.rstrip()
AttributeError: 'list' object has no attribute 'rstrip'

2021-03-14 15:46:33,231 - nornir.core.task -    ERROR -      start() - Host 'RR-1': task 'load_variable' failed with traceback:
Traceback (most recent call last):
  File "/usr/local/lib/python3.9/site-packages/nornir/core/task.py", line 98, in start
    r = self.task(self, **self.params)
  File "/Users/vishalgajjar/Documents/lab/bgp config/int_ospf_bgp_config.py", line 16, in load_variable
    int_ospf_bgp_configuration(task)
  File "/Users/vishalgajjar/Documents/lab/bgp config/int_ospf_bgp_config.py", line 28, in int_ospf_bgp_configuration
    show_status_ospf_bgp(task)
  File "/Users/vishalgajjar/Documents/lab/bgp config/int_ospf_bgp_config.py", line 34, in show_status_ospf_bgp
    task.run(task=netmiko_send_command, command_string=[
  File "/usr/local/lib/python3.9/site-packages/nornir/core/task.py", line 168, in run
    raise NornirSubTaskError(task=run_task, result=r)
nornir.core.exceptions.NornirSubTaskError: Subtask: netmiko_send_command (failed)


2021-03-14 15:46:33,486 - nornir.core.task -    ERROR -      start() - Host 'RR-2': task 'netmiko_send_command' failed with traceback:
Traceback (most recent call last):
  File "/usr/local/lib/python3.9/site-packages/nornir/core/task.py", line 98, in start
    r = self.task(self, **self.params)
  File "/usr/local/lib/python3.9/site-packages/nornir_netmiko/tasks/netmiko_send_command.py", line 32, in netmiko_send_command
    result = net_connect.send_command(command_string, **kwargs)
  File "/usr/local/lib/python3.9/site-packages/netmiko/utilities.py", line 429, in wrapper_decorator
    return func(self, *args, **kwargs)
  File "/usr/local/lib/python3.9/site-packages/netmiko/base_connection.py", line 1473, in send_command
    command_string = self.normalize_cmd(command_string)
  File "/usr/local/lib/python3.9/site-packages/netmiko/base_connection.py", line 1632, in normalize_cmd
    command = command.rstrip()
AttributeError: 'list' object has no attribute 'rstrip'

2021-03-14 15:46:33,486 - nornir.core.task -    ERROR -      start() - Host 'RR-2': task 'load_variable' failed with traceback:
Traceback (most recent call last):
  File "/usr/local/lib/python3.9/site-packages/nornir/core/task.py", line 98, in start
    r = self.task(self, **self.params)
  File "/Users/vishalgajjar/Documents/lab/bgp config/int_ospf_bgp_config.py", line 16, in load_variable
    int_ospf_bgp_configuration(task)
  File "/Users/vishalgajjar/Documents/lab/bgp config/int_ospf_bgp_config.py", line 28, in int_ospf_bgp_configuration
    show_status_ospf_bgp(task)
  File "/Users/vishalgajjar/Documents/lab/bgp config/int_ospf_bgp_config.py", line 34, in show_status_ospf_bgp
    task.run(task=netmiko_send_command, command_string=[
  File "/usr/local/lib/python3.9/site-packages/nornir/core/task.py", line 168, in run
    raise NornirSubTaskError(task=run_task, result=r)
nornir.core.exceptions.NornirSubTaskError: Subtask: netmiko_send_command (failed)


2021-03-14 15:49:40,690 -  nornir.core -     INFO -        run() - Running task 'load_variable' with args {} on 6 hosts
2021-03-14 15:49:55,279 - nornir.core.task -    ERROR -      start() - Host 'R2': task 'netmiko_send_command' failed with traceback:
Traceback (most recent call last):
  File "/usr/local/lib/python3.9/site-packages/nornir/core/task.py", line 98, in start
    r = self.task(self, **self.params)
  File "/usr/local/lib/python3.9/site-packages/nornir_netmiko/tasks/netmiko_send_command.py", line 32, in netmiko_send_command
    result = net_connect.send_command(command_string, **kwargs)
  File "/usr/local/lib/python3.9/site-packages/netmiko/utilities.py", line 429, in wrapper_decorator
    return func(self, *args, **kwargs)
  File "/usr/local/lib/python3.9/site-packages/netmiko/base_connection.py", line 1473, in send_command
    command_string = self.normalize_cmd(command_string)
  File "/usr/local/lib/python3.9/site-packages/netmiko/base_connection.py", line 1632, in normalize_cmd
    command = command.rstrip()
AttributeError: 'list' object has no attribute 'rstrip'

2021-03-14 15:49:55,279 - nornir.core.task -    ERROR -      start() - Host 'R2': task 'load_variable' failed with traceback:
Traceback (most recent call last):
  File "/usr/local/lib/python3.9/site-packages/nornir/core/task.py", line 98, in start
    r = self.task(self, **self.params)
  File "/Users/vishalgajjar/Documents/lab/bgp config/int_ospf_bgp_config.py", line 16, in load_variable
    int_ospf_bgp_configuration(task)
  File "/Users/vishalgajjar/Documents/lab/bgp config/int_ospf_bgp_config.py", line 28, in int_ospf_bgp_configuration
    show_status_ospf_bgp(task)
  File "/Users/vishalgajjar/Documents/lab/bgp config/int_ospf_bgp_config.py", line 34, in show_status_ospf_bgp
    task.run(task=netmiko_send_command, command_string=[
  File "/usr/local/lib/python3.9/site-packages/nornir/core/task.py", line 168, in run
    raise NornirSubTaskError(task=run_task, result=r)
nornir.core.exceptions.NornirSubTaskError: Subtask: netmiko_send_command (failed)


2021-03-14 15:49:55,412 - nornir.core.task -    ERROR -      start() - Host 'R3': task 'netmiko_send_command' failed with traceback:
Traceback (most recent call last):
  File "/usr/local/lib/python3.9/site-packages/nornir/core/task.py", line 98, in start
    r = self.task(self, **self.params)
  File "/usr/local/lib/python3.9/site-packages/nornir_netmiko/tasks/netmiko_send_command.py", line 32, in netmiko_send_command
    result = net_connect.send_command(command_string, **kwargs)
  File "/usr/local/lib/python3.9/site-packages/netmiko/utilities.py", line 429, in wrapper_decorator
    return func(self, *args, **kwargs)
  File "/usr/local/lib/python3.9/site-packages/netmiko/base_connection.py", line 1473, in send_command
    command_string = self.normalize_cmd(command_string)
  File "/usr/local/lib/python3.9/site-packages/netmiko/base_connection.py", line 1632, in normalize_cmd
    command = command.rstrip()
AttributeError: 'list' object has no attribute 'rstrip'

2021-03-14 15:49:55,412 - nornir.core.task -    ERROR -      start() - Host 'R3': task 'load_variable' failed with traceback:
Traceback (most recent call last):
  File "/usr/local/lib/python3.9/site-packages/nornir/core/task.py", line 98, in start
    r = self.task(self, **self.params)
  File "/Users/vishalgajjar/Documents/lab/bgp config/int_ospf_bgp_config.py", line 16, in load_variable
    int_ospf_bgp_configuration(task)
  File "/Users/vishalgajjar/Documents/lab/bgp config/int_ospf_bgp_config.py", line 28, in int_ospf_bgp_configuration
    show_status_ospf_bgp(task)
  File "/Users/vishalgajjar/Documents/lab/bgp config/int_ospf_bgp_config.py", line 34, in show_status_ospf_bgp
    task.run(task=netmiko_send_command, command_string=[
  File "/usr/local/lib/python3.9/site-packages/nornir/core/task.py", line 168, in run
    raise NornirSubTaskError(task=run_task, result=r)
nornir.core.exceptions.NornirSubTaskError: Subtask: netmiko_send_command (failed)


2021-03-14 15:49:55,420 - nornir.core.task -    ERROR -      start() - Host 'R1': task 'netmiko_send_command' failed with traceback:
Traceback (most recent call last):
  File "/usr/local/lib/python3.9/site-packages/nornir/core/task.py", line 98, in start
    r = self.task(self, **self.params)
  File "/usr/local/lib/python3.9/site-packages/nornir_netmiko/tasks/netmiko_send_command.py", line 32, in netmiko_send_command
    result = net_connect.send_command(command_string, **kwargs)
  File "/usr/local/lib/python3.9/site-packages/netmiko/utilities.py", line 429, in wrapper_decorator
    return func(self, *args, **kwargs)
  File "/usr/local/lib/python3.9/site-packages/netmiko/base_connection.py", line 1473, in send_command
    command_string = self.normalize_cmd(command_string)
  File "/usr/local/lib/python3.9/site-packages/netmiko/base_connection.py", line 1632, in normalize_cmd
    command = command.rstrip()
AttributeError: 'list' object has no attribute 'rstrip'

2021-03-14 15:49:55,421 - nornir.core.task -    ERROR -      start() - Host 'R1': task 'load_variable' failed with traceback:
Traceback (most recent call last):
  File "/usr/local/lib/python3.9/site-packages/nornir/core/task.py", line 98, in start
    r = self.task(self, **self.params)
  File "/Users/vishalgajjar/Documents/lab/bgp config/int_ospf_bgp_config.py", line 16, in load_variable
    int_ospf_bgp_configuration(task)
  File "/Users/vishalgajjar/Documents/lab/bgp config/int_ospf_bgp_config.py", line 28, in int_ospf_bgp_configuration
    show_status_ospf_bgp(task)
  File "/Users/vishalgajjar/Documents/lab/bgp config/int_ospf_bgp_config.py", line 34, in show_status_ospf_bgp
    task.run(task=netmiko_send_command, command_string=[
  File "/usr/local/lib/python3.9/site-packages/nornir/core/task.py", line 168, in run
    raise NornirSubTaskError(task=run_task, result=r)
nornir.core.exceptions.NornirSubTaskError: Subtask: netmiko_send_command (failed)


2021-03-14 15:49:55,694 - nornir.core.task -    ERROR -      start() - Host 'R4': task 'netmiko_send_command' failed with traceback:
Traceback (most recent call last):
  File "/usr/local/lib/python3.9/site-packages/nornir/core/task.py", line 98, in start
    r = self.task(self, **self.params)
  File "/usr/local/lib/python3.9/site-packages/nornir_netmiko/tasks/netmiko_send_command.py", line 32, in netmiko_send_command
    result = net_connect.send_command(command_string, **kwargs)
  File "/usr/local/lib/python3.9/site-packages/netmiko/utilities.py", line 429, in wrapper_decorator
    return func(self, *args, **kwargs)
  File "/usr/local/lib/python3.9/site-packages/netmiko/base_connection.py", line 1473, in send_command
    command_string = self.normalize_cmd(command_string)
  File "/usr/local/lib/python3.9/site-packages/netmiko/base_connection.py", line 1632, in normalize_cmd
    command = command.rstrip()
AttributeError: 'list' object has no attribute 'rstrip'

2021-03-14 15:49:55,694 - nornir.core.task -    ERROR -      start() - Host 'R4': task 'load_variable' failed with traceback:
Traceback (most recent call last):
  File "/usr/local/lib/python3.9/site-packages/nornir/core/task.py", line 98, in start
    r = self.task(self, **self.params)
  File "/Users/vishalgajjar/Documents/lab/bgp config/int_ospf_bgp_config.py", line 16, in load_variable
    int_ospf_bgp_configuration(task)
  File "/Users/vishalgajjar/Documents/lab/bgp config/int_ospf_bgp_config.py", line 28, in int_ospf_bgp_configuration
    show_status_ospf_bgp(task)
  File "/Users/vishalgajjar/Documents/lab/bgp config/int_ospf_bgp_config.py", line 34, in show_status_ospf_bgp
    task.run(task=netmiko_send_command, command_string=[
  File "/usr/local/lib/python3.9/site-packages/nornir/core/task.py", line 168, in run
    raise NornirSubTaskError(task=run_task, result=r)
nornir.core.exceptions.NornirSubTaskError: Subtask: netmiko_send_command (failed)


2021-03-14 15:49:57,571 - nornir.core.task -    ERROR -      start() - Host 'RR-1': task 'netmiko_send_command' failed with traceback:
Traceback (most recent call last):
  File "/usr/local/lib/python3.9/site-packages/nornir/core/task.py", line 98, in start
    r = self.task(self, **self.params)
  File "/usr/local/lib/python3.9/site-packages/nornir_netmiko/tasks/netmiko_send_command.py", line 32, in netmiko_send_command
    result = net_connect.send_command(command_string, **kwargs)
  File "/usr/local/lib/python3.9/site-packages/netmiko/utilities.py", line 429, in wrapper_decorator
    return func(self, *args, **kwargs)
  File "/usr/local/lib/python3.9/site-packages/netmiko/base_connection.py", line 1473, in send_command
    command_string = self.normalize_cmd(command_string)
  File "/usr/local/lib/python3.9/site-packages/netmiko/base_connection.py", line 1632, in normalize_cmd
    command = command.rstrip()
AttributeError: 'list' object has no attribute 'rstrip'

2021-03-14 15:49:57,571 - nornir.core.task -    ERROR -      start() - Host 'RR-1': task 'load_variable' failed with traceback:
Traceback (most recent call last):
  File "/usr/local/lib/python3.9/site-packages/nornir/core/task.py", line 98, in start
    r = self.task(self, **self.params)
  File "/Users/vishalgajjar/Documents/lab/bgp config/int_ospf_bgp_config.py", line 16, in load_variable
    int_ospf_bgp_configuration(task)
  File "/Users/vishalgajjar/Documents/lab/bgp config/int_ospf_bgp_config.py", line 28, in int_ospf_bgp_configuration
    show_status_ospf_bgp(task)
  File "/Users/vishalgajjar/Documents/lab/bgp config/int_ospf_bgp_config.py", line 34, in show_status_ospf_bgp
    task.run(task=netmiko_send_command, command_string=[
  File "/usr/local/lib/python3.9/site-packages/nornir/core/task.py", line 168, in run
    raise NornirSubTaskError(task=run_task, result=r)
nornir.core.exceptions.NornirSubTaskError: Subtask: netmiko_send_command (failed)


2021-03-14 15:49:58,497 - nornir.core.task -    ERROR -      start() - Host 'RR-2': task 'netmiko_send_command' failed with traceback:
Traceback (most recent call last):
  File "/usr/local/lib/python3.9/site-packages/nornir/core/task.py", line 98, in start
    r = self.task(self, **self.params)
  File "/usr/local/lib/python3.9/site-packages/nornir_netmiko/tasks/netmiko_send_command.py", line 32, in netmiko_send_command
    result = net_connect.send_command(command_string, **kwargs)
  File "/usr/local/lib/python3.9/site-packages/netmiko/utilities.py", line 429, in wrapper_decorator
    return func(self, *args, **kwargs)
  File "/usr/local/lib/python3.9/site-packages/netmiko/base_connection.py", line 1473, in send_command
    command_string = self.normalize_cmd(command_string)
  File "/usr/local/lib/python3.9/site-packages/netmiko/base_connection.py", line 1632, in normalize_cmd
    command = command.rstrip()
AttributeError: 'list' object has no attribute 'rstrip'

2021-03-14 15:49:58,497 - nornir.core.task -    ERROR -      start() - Host 'RR-2': task 'load_variable' failed with traceback:
Traceback (most recent call last):
  File "/usr/local/lib/python3.9/site-packages/nornir/core/task.py", line 98, in start
    r = self.task(self, **self.params)
  File "/Users/vishalgajjar/Documents/lab/bgp config/int_ospf_bgp_config.py", line 16, in load_variable
    int_ospf_bgp_configuration(task)
  File "/Users/vishalgajjar/Documents/lab/bgp config/int_ospf_bgp_config.py", line 28, in int_ospf_bgp_configuration
    show_status_ospf_bgp(task)
  File "/Users/vishalgajjar/Documents/lab/bgp config/int_ospf_bgp_config.py", line 34, in show_status_ospf_bgp
    task.run(task=netmiko_send_command, command_string=[
  File "/usr/local/lib/python3.9/site-packages/nornir/core/task.py", line 168, in run
    raise NornirSubTaskError(task=run_task, result=r)
nornir.core.exceptions.NornirSubTaskError: Subtask: netmiko_send_command (failed)


2021-03-14 16:00:30,592 -  nornir.core -     INFO -        run() - Running task 'load_variable' with args {} on 6 hosts
2021-03-14 16:00:48,877 -  nornir.core -     INFO -        run() - Running task 'show_status_ospf_bgp' with args {} on 6 hosts
2021-03-14 16:00:48,959 - nornir.core.task -    ERROR -      start() - Host 'R4': task 'netmiko_send_command' failed with traceback:
Traceback (most recent call last):
  File "/usr/local/lib/python3.9/site-packages/nornir/core/task.py", line 98, in start
    r = self.task(self, **self.params)
  File "/usr/local/lib/python3.9/site-packages/nornir_netmiko/tasks/netmiko_send_command.py", line 32, in netmiko_send_command
    result = net_connect.send_command(command_string, **kwargs)
  File "/usr/local/lib/python3.9/site-packages/netmiko/utilities.py", line 429, in wrapper_decorator
    return func(self, *args, **kwargs)
  File "/usr/local/lib/python3.9/site-packages/netmiko/base_connection.py", line 1473, in send_command
    command_string = self.normalize_cmd(command_string)
  File "/usr/local/lib/python3.9/site-packages/netmiko/base_connection.py", line 1632, in normalize_cmd
    command = command.rstrip()
AttributeError: 'list' object has no attribute 'rstrip'

2021-03-14 16:00:48,960 - nornir.core.task -    ERROR -      start() - Host 'R4': task 'show_status_ospf_bgp' failed with traceback:
Traceback (most recent call last):
  File "/usr/local/lib/python3.9/site-packages/nornir/core/task.py", line 98, in start
    r = self.task(self, **self.params)
  File "/Users/vishalgajjar/Documents/lab/bgp config/int_ospf_bgp_config.py", line 34, in show_status_ospf_bgp
    show_cmd = task.run(task=netmiko_send_command, command_string=[
  File "/usr/local/lib/python3.9/site-packages/nornir/core/task.py", line 168, in run
    raise NornirSubTaskError(task=run_task, result=r)
nornir.core.exceptions.NornirSubTaskError: Subtask: netmiko_send_command (failed)


2021-03-14 16:00:48,963 - nornir.core.task -    ERROR -      start() - Host 'RR-1': task 'netmiko_send_command' failed with traceback:
Traceback (most recent call last):
  File "/usr/local/lib/python3.9/site-packages/nornir/core/task.py", line 98, in start
    r = self.task(self, **self.params)
  File "/usr/local/lib/python3.9/site-packages/nornir_netmiko/tasks/netmiko_send_command.py", line 32, in netmiko_send_command
    result = net_connect.send_command(command_string, **kwargs)
  File "/usr/local/lib/python3.9/site-packages/netmiko/utilities.py", line 429, in wrapper_decorator
    return func(self, *args, **kwargs)
  File "/usr/local/lib/python3.9/site-packages/netmiko/base_connection.py", line 1473, in send_command
    command_string = self.normalize_cmd(command_string)
  File "/usr/local/lib/python3.9/site-packages/netmiko/base_connection.py", line 1632, in normalize_cmd
    command = command.rstrip()
AttributeError: 'list' object has no attribute 'rstrip'

2021-03-14 16:00:48,964 - nornir.core.task -    ERROR -      start() - Host 'RR-1': task 'show_status_ospf_bgp' failed with traceback:
Traceback (most recent call last):
  File "/usr/local/lib/python3.9/site-packages/nornir/core/task.py", line 98, in start
    r = self.task(self, **self.params)
  File "/Users/vishalgajjar/Documents/lab/bgp config/int_ospf_bgp_config.py", line 34, in show_status_ospf_bgp
    show_cmd = task.run(task=netmiko_send_command, command_string=[
  File "/usr/local/lib/python3.9/site-packages/nornir/core/task.py", line 168, in run
    raise NornirSubTaskError(task=run_task, result=r)
nornir.core.exceptions.NornirSubTaskError: Subtask: netmiko_send_command (failed)


2021-03-14 16:00:48,989 - nornir.core.task -    ERROR -      start() - Host 'RR-2': task 'netmiko_send_command' failed with traceback:
Traceback (most recent call last):
  File "/usr/local/lib/python3.9/site-packages/nornir/core/task.py", line 98, in start
    r = self.task(self, **self.params)
  File "/usr/local/lib/python3.9/site-packages/nornir_netmiko/tasks/netmiko_send_command.py", line 32, in netmiko_send_command
    result = net_connect.send_command(command_string, **kwargs)
  File "/usr/local/lib/python3.9/site-packages/netmiko/utilities.py", line 429, in wrapper_decorator
    return func(self, *args, **kwargs)
  File "/usr/local/lib/python3.9/site-packages/netmiko/base_connection.py", line 1473, in send_command
    command_string = self.normalize_cmd(command_string)
  File "/usr/local/lib/python3.9/site-packages/netmiko/base_connection.py", line 1632, in normalize_cmd
    command = command.rstrip()
AttributeError: 'list' object has no attribute 'rstrip'

2021-03-14 16:00:48,989 - nornir.core.task -    ERROR -      start() - Host 'RR-2': task 'show_status_ospf_bgp' failed with traceback:
Traceback (most recent call last):
  File "/usr/local/lib/python3.9/site-packages/nornir/core/task.py", line 98, in start
    r = self.task(self, **self.params)
  File "/Users/vishalgajjar/Documents/lab/bgp config/int_ospf_bgp_config.py", line 34, in show_status_ospf_bgp
    show_cmd = task.run(task=netmiko_send_command, command_string=[
  File "/usr/local/lib/python3.9/site-packages/nornir/core/task.py", line 168, in run
    raise NornirSubTaskError(task=run_task, result=r)
nornir.core.exceptions.NornirSubTaskError: Subtask: netmiko_send_command (failed)


2021-03-14 16:00:49,044 - nornir.core.task -    ERROR -      start() - Host 'R2': task 'netmiko_send_command' failed with traceback:
Traceback (most recent call last):
  File "/usr/local/lib/python3.9/site-packages/nornir/core/task.py", line 98, in start
    r = self.task(self, **self.params)
  File "/usr/local/lib/python3.9/site-packages/nornir_netmiko/tasks/netmiko_send_command.py", line 32, in netmiko_send_command
    result = net_connect.send_command(command_string, **kwargs)
  File "/usr/local/lib/python3.9/site-packages/netmiko/utilities.py", line 429, in wrapper_decorator
    return func(self, *args, **kwargs)
  File "/usr/local/lib/python3.9/site-packages/netmiko/base_connection.py", line 1473, in send_command
    command_string = self.normalize_cmd(command_string)
  File "/usr/local/lib/python3.9/site-packages/netmiko/base_connection.py", line 1632, in normalize_cmd
    command = command.rstrip()
AttributeError: 'list' object has no attribute 'rstrip'

2021-03-14 16:00:49,044 - nornir.core.task -    ERROR -      start() - Host 'R3': task 'netmiko_send_command' failed with traceback:
Traceback (most recent call last):
  File "/usr/local/lib/python3.9/site-packages/nornir/core/task.py", line 98, in start
    r = self.task(self, **self.params)
  File "/usr/local/lib/python3.9/site-packages/nornir_netmiko/tasks/netmiko_send_command.py", line 32, in netmiko_send_command
    result = net_connect.send_command(command_string, **kwargs)
  File "/usr/local/lib/python3.9/site-packages/netmiko/utilities.py", line 429, in wrapper_decorator
    return func(self, *args, **kwargs)
  File "/usr/local/lib/python3.9/site-packages/netmiko/base_connection.py", line 1473, in send_command
    command_string = self.normalize_cmd(command_string)
  File "/usr/local/lib/python3.9/site-packages/netmiko/base_connection.py", line 1632, in normalize_cmd
    command = command.rstrip()
AttributeError: 'list' object has no attribute 'rstrip'

2021-03-14 16:00:49,045 - nornir.core.task -    ERROR -      start() - Host 'R2': task 'show_status_ospf_bgp' failed with traceback:
Traceback (most recent call last):
  File "/usr/local/lib/python3.9/site-packages/nornir/core/task.py", line 98, in start
    r = self.task(self, **self.params)
  File "/Users/vishalgajjar/Documents/lab/bgp config/int_ospf_bgp_config.py", line 34, in show_status_ospf_bgp
    show_cmd = task.run(task=netmiko_send_command, command_string=[
  File "/usr/local/lib/python3.9/site-packages/nornir/core/task.py", line 168, in run
    raise NornirSubTaskError(task=run_task, result=r)
nornir.core.exceptions.NornirSubTaskError: Subtask: netmiko_send_command (failed)


2021-03-14 16:00:49,045 - nornir.core.task -    ERROR -      start() - Host 'R3': task 'show_status_ospf_bgp' failed with traceback:
Traceback (most recent call last):
  File "/usr/local/lib/python3.9/site-packages/nornir/core/task.py", line 98, in start
    r = self.task(self, **self.params)
  File "/Users/vishalgajjar/Documents/lab/bgp config/int_ospf_bgp_config.py", line 34, in show_status_ospf_bgp
    show_cmd = task.run(task=netmiko_send_command, command_string=[
  File "/usr/local/lib/python3.9/site-packages/nornir/core/task.py", line 168, in run
    raise NornirSubTaskError(task=run_task, result=r)
nornir.core.exceptions.NornirSubTaskError: Subtask: netmiko_send_command (failed)


2021-03-14 16:00:49,169 - nornir.core.task -    ERROR -      start() - Host 'R1': task 'netmiko_send_command' failed with traceback:
Traceback (most recent call last):
  File "/usr/local/lib/python3.9/site-packages/nornir/core/task.py", line 98, in start
    r = self.task(self, **self.params)
  File "/usr/local/lib/python3.9/site-packages/nornir_netmiko/tasks/netmiko_send_command.py", line 32, in netmiko_send_command
    result = net_connect.send_command(command_string, **kwargs)
  File "/usr/local/lib/python3.9/site-packages/netmiko/utilities.py", line 429, in wrapper_decorator
    return func(self, *args, **kwargs)
  File "/usr/local/lib/python3.9/site-packages/netmiko/base_connection.py", line 1473, in send_command
    command_string = self.normalize_cmd(command_string)
  File "/usr/local/lib/python3.9/site-packages/netmiko/base_connection.py", line 1632, in normalize_cmd
    command = command.rstrip()
AttributeError: 'list' object has no attribute 'rstrip'

2021-03-14 16:00:49,169 - nornir.core.task -    ERROR -      start() - Host 'R1': task 'show_status_ospf_bgp' failed with traceback:
Traceback (most recent call last):
  File "/usr/local/lib/python3.9/site-packages/nornir/core/task.py", line 98, in start
    r = self.task(self, **self.params)
  File "/Users/vishalgajjar/Documents/lab/bgp config/int_ospf_bgp_config.py", line 34, in show_status_ospf_bgp
    show_cmd = task.run(task=netmiko_send_command, command_string=[
  File "/usr/local/lib/python3.9/site-packages/nornir/core/task.py", line 168, in run
    raise NornirSubTaskError(task=run_task, result=r)
nornir.core.exceptions.NornirSubTaskError: Subtask: netmiko_send_command (failed)


2021-03-15 11:51:16,999 -  nornir.core -     INFO -        run() - Running task 'load_variable' with args {} on 6 hosts
2021-03-15 11:51:37,243 -  nornir.core -     INFO -        run() - Running task 'netmiko_send_command' with args {'command_string': ['show ip int br', 'show ip ospf neighbor', 'show ip bgp summary']} on 6 hosts
2021-03-15 11:51:37,374 - nornir.core.task -    ERROR -      start() - Host 'R3': task 'netmiko_send_command' failed with traceback:
Traceback (most recent call last):
  File "/usr/local/lib/python3.9/site-packages/nornir/core/task.py", line 98, in start
    r = self.task(self, **self.params)
  File "/usr/local/lib/python3.9/site-packages/nornir_netmiko/tasks/netmiko_send_command.py", line 32, in netmiko_send_command
    result = net_connect.send_command(command_string, **kwargs)
  File "/usr/local/lib/python3.9/site-packages/netmiko/utilities.py", line 429, in wrapper_decorator
    return func(self, *args, **kwargs)
  File "/usr/local/lib/python3.9/site-packages/netmiko/base_connection.py", line 1473, in send_command
    command_string = self.normalize_cmd(command_string)
  File "/usr/local/lib/python3.9/site-packages/netmiko/base_connection.py", line 1632, in normalize_cmd
    command = command.rstrip()
AttributeError: 'list' object has no attribute 'rstrip'

2021-03-15 11:51:37,391 - nornir.core.task -    ERROR -      start() - Host 'RR-2': task 'netmiko_send_command' failed with traceback:
Traceback (most recent call last):
  File "/usr/local/lib/python3.9/site-packages/nornir/core/task.py", line 98, in start
    r = self.task(self, **self.params)
  File "/usr/local/lib/python3.9/site-packages/nornir_netmiko/tasks/netmiko_send_command.py", line 32, in netmiko_send_command
    result = net_connect.send_command(command_string, **kwargs)
  File "/usr/local/lib/python3.9/site-packages/netmiko/utilities.py", line 429, in wrapper_decorator
    return func(self, *args, **kwargs)
  File "/usr/local/lib/python3.9/site-packages/netmiko/base_connection.py", line 1473, in send_command
    command_string = self.normalize_cmd(command_string)
  File "/usr/local/lib/python3.9/site-packages/netmiko/base_connection.py", line 1632, in normalize_cmd
    command = command.rstrip()
AttributeError: 'list' object has no attribute 'rstrip'

2021-03-15 11:51:37,457 - nornir.core.task -    ERROR -      start() - Host 'R2': task 'netmiko_send_command' failed with traceback:
Traceback (most recent call last):
  File "/usr/local/lib/python3.9/site-packages/nornir/core/task.py", line 98, in start
    r = self.task(self, **self.params)
  File "/usr/local/lib/python3.9/site-packages/nornir_netmiko/tasks/netmiko_send_command.py", line 32, in netmiko_send_command
    result = net_connect.send_command(command_string, **kwargs)
  File "/usr/local/lib/python3.9/site-packages/netmiko/utilities.py", line 429, in wrapper_decorator
    return func(self, *args, **kwargs)
  File "/usr/local/lib/python3.9/site-packages/netmiko/base_connection.py", line 1473, in send_command
    command_string = self.normalize_cmd(command_string)
  File "/usr/local/lib/python3.9/site-packages/netmiko/base_connection.py", line 1632, in normalize_cmd
    command = command.rstrip()
AttributeError: 'list' object has no attribute 'rstrip'

2021-03-15 11:51:37,515 - nornir.core.task -    ERROR -      start() - Host 'RR-1': task 'netmiko_send_command' failed with traceback:
Traceback (most recent call last):
  File "/usr/local/lib/python3.9/site-packages/nornir/core/task.py", line 98, in start
    r = self.task(self, **self.params)
  File "/usr/local/lib/python3.9/site-packages/nornir_netmiko/tasks/netmiko_send_command.py", line 32, in netmiko_send_command
    result = net_connect.send_command(command_string, **kwargs)
  File "/usr/local/lib/python3.9/site-packages/netmiko/utilities.py", line 429, in wrapper_decorator
    return func(self, *args, **kwargs)
  File "/usr/local/lib/python3.9/site-packages/netmiko/base_connection.py", line 1473, in send_command
    command_string = self.normalize_cmd(command_string)
  File "/usr/local/lib/python3.9/site-packages/netmiko/base_connection.py", line 1632, in normalize_cmd
    command = command.rstrip()
AttributeError: 'list' object has no attribute 'rstrip'

2021-03-15 11:51:37,541 - nornir.core.task -    ERROR -      start() - Host 'R4': task 'netmiko_send_command' failed with traceback:
Traceback (most recent call last):
  File "/usr/local/lib/python3.9/site-packages/nornir/core/task.py", line 98, in start
    r = self.task(self, **self.params)
  File "/usr/local/lib/python3.9/site-packages/nornir_netmiko/tasks/netmiko_send_command.py", line 32, in netmiko_send_command
    result = net_connect.send_command(command_string, **kwargs)
  File "/usr/local/lib/python3.9/site-packages/netmiko/utilities.py", line 429, in wrapper_decorator
    return func(self, *args, **kwargs)
  File "/usr/local/lib/python3.9/site-packages/netmiko/base_connection.py", line 1473, in send_command
    command_string = self.normalize_cmd(command_string)
  File "/usr/local/lib/python3.9/site-packages/netmiko/base_connection.py", line 1632, in normalize_cmd
    command = command.rstrip()
AttributeError: 'list' object has no attribute 'rstrip'

2021-03-15 11:51:37,542 - nornir.core.task -    ERROR -      start() - Host 'R1': task 'netmiko_send_command' failed with traceback:
Traceback (most recent call last):
  File "/usr/local/lib/python3.9/site-packages/nornir/core/task.py", line 98, in start
    r = self.task(self, **self.params)
  File "/usr/local/lib/python3.9/site-packages/nornir_netmiko/tasks/netmiko_send_command.py", line 32, in netmiko_send_command
    result = net_connect.send_command(command_string, **kwargs)
  File "/usr/local/lib/python3.9/site-packages/netmiko/utilities.py", line 429, in wrapper_decorator
    return func(self, *args, **kwargs)
  File "/usr/local/lib/python3.9/site-packages/netmiko/base_connection.py", line 1473, in send_command
    command_string = self.normalize_cmd(command_string)
  File "/usr/local/lib/python3.9/site-packages/netmiko/base_connection.py", line 1632, in normalize_cmd
    command = command.rstrip()
AttributeError: 'list' object has no attribute 'rstrip'

2021-03-15 11:55:25,280 -  nornir.core -     INFO -        run() - Running task 'load_variable' with args {} on 6 hosts
2021-03-15 11:55:44,003 -  nornir.core -     INFO -        run() - Running task 'netmiko_send_command' with args {'command_string': ['show ip int br', 'show ip ospf neighbor', 'show ip bgp summary']} on 6 hosts
2021-03-15 11:55:44,088 - nornir.core.task -    ERROR -      start() - Host 'RR-2': task 'netmiko_send_command' failed with traceback:
Traceback (most recent call last):
  File "/usr/local/lib/python3.9/site-packages/nornir/core/task.py", line 98, in start
    r = self.task(self, **self.params)
  File "/usr/local/lib/python3.9/site-packages/nornir_netmiko/tasks/netmiko_send_command.py", line 32, in netmiko_send_command
    result = net_connect.send_command(command_string, **kwargs)
  File "/usr/local/lib/python3.9/site-packages/netmiko/utilities.py", line 429, in wrapper_decorator
    return func(self, *args, **kwargs)
  File "/usr/local/lib/python3.9/site-packages/netmiko/base_connection.py", line 1473, in send_command
    command_string = self.normalize_cmd(command_string)
  File "/usr/local/lib/python3.9/site-packages/netmiko/base_connection.py", line 1632, in normalize_cmd
    command = command.rstrip()
AttributeError: 'list' object has no attribute 'rstrip'

2021-03-15 11:55:44,089 - nornir.core.task -    ERROR -      start() - Host 'R1': task 'netmiko_send_command' failed with traceback:
Traceback (most recent call last):
  File "/usr/local/lib/python3.9/site-packages/nornir/core/task.py", line 98, in start
    r = self.task(self, **self.params)
  File "/usr/local/lib/python3.9/site-packages/nornir_netmiko/tasks/netmiko_send_command.py", line 32, in netmiko_send_command
    result = net_connect.send_command(command_string, **kwargs)
  File "/usr/local/lib/python3.9/site-packages/netmiko/utilities.py", line 429, in wrapper_decorator
    return func(self, *args, **kwargs)
  File "/usr/local/lib/python3.9/site-packages/netmiko/base_connection.py", line 1473, in send_command
    command_string = self.normalize_cmd(command_string)
  File "/usr/local/lib/python3.9/site-packages/netmiko/base_connection.py", line 1632, in normalize_cmd
    command = command.rstrip()
AttributeError: 'list' object has no attribute 'rstrip'

2021-03-15 11:55:44,147 - nornir.core.task -    ERROR -      start() - Host 'R4': task 'netmiko_send_command' failed with traceback:
Traceback (most recent call last):
  File "/usr/local/lib/python3.9/site-packages/nornir/core/task.py", line 98, in start
    r = self.task(self, **self.params)
  File "/usr/local/lib/python3.9/site-packages/nornir_netmiko/tasks/netmiko_send_command.py", line 32, in netmiko_send_command
    result = net_connect.send_command(command_string, **kwargs)
  File "/usr/local/lib/python3.9/site-packages/netmiko/utilities.py", line 429, in wrapper_decorator
    return func(self, *args, **kwargs)
  File "/usr/local/lib/python3.9/site-packages/netmiko/base_connection.py", line 1473, in send_command
    command_string = self.normalize_cmd(command_string)
  File "/usr/local/lib/python3.9/site-packages/netmiko/base_connection.py", line 1632, in normalize_cmd
    command = command.rstrip()
AttributeError: 'list' object has no attribute 'rstrip'

2021-03-15 11:55:44,188 - nornir.core.task -    ERROR -      start() - Host 'R2': task 'netmiko_send_command' failed with traceback:
Traceback (most recent call last):
  File "/usr/local/lib/python3.9/site-packages/nornir/core/task.py", line 98, in start
    r = self.task(self, **self.params)
  File "/usr/local/lib/python3.9/site-packages/nornir_netmiko/tasks/netmiko_send_command.py", line 32, in netmiko_send_command
    result = net_connect.send_command(command_string, **kwargs)
  File "/usr/local/lib/python3.9/site-packages/netmiko/utilities.py", line 429, in wrapper_decorator
    return func(self, *args, **kwargs)
  File "/usr/local/lib/python3.9/site-packages/netmiko/base_connection.py", line 1473, in send_command
    command_string = self.normalize_cmd(command_string)
  File "/usr/local/lib/python3.9/site-packages/netmiko/base_connection.py", line 1632, in normalize_cmd
    command = command.rstrip()
AttributeError: 'list' object has no attribute 'rstrip'

2021-03-15 11:55:44,199 - nornir.core.task -    ERROR -      start() - Host 'R3': task 'netmiko_send_command' failed with traceback:
Traceback (most recent call last):
  File "/usr/local/lib/python3.9/site-packages/nornir/core/task.py", line 98, in start
    r = self.task(self, **self.params)
  File "/usr/local/lib/python3.9/site-packages/nornir_netmiko/tasks/netmiko_send_command.py", line 32, in netmiko_send_command
    result = net_connect.send_command(command_string, **kwargs)
  File "/usr/local/lib/python3.9/site-packages/netmiko/utilities.py", line 429, in wrapper_decorator
    return func(self, *args, **kwargs)
  File "/usr/local/lib/python3.9/site-packages/netmiko/base_connection.py", line 1473, in send_command
    command_string = self.normalize_cmd(command_string)
  File "/usr/local/lib/python3.9/site-packages/netmiko/base_connection.py", line 1632, in normalize_cmd
    command = command.rstrip()
AttributeError: 'list' object has no attribute 'rstrip'

2021-03-15 11:55:44,280 - nornir.core.task -    ERROR -      start() - Host 'RR-1': task 'netmiko_send_command' failed with traceback:
Traceback (most recent call last):
  File "/usr/local/lib/python3.9/site-packages/nornir/core/task.py", line 98, in start
    r = self.task(self, **self.params)
  File "/usr/local/lib/python3.9/site-packages/nornir_netmiko/tasks/netmiko_send_command.py", line 32, in netmiko_send_command
    result = net_connect.send_command(command_string, **kwargs)
  File "/usr/local/lib/python3.9/site-packages/netmiko/utilities.py", line 429, in wrapper_decorator
    return func(self, *args, **kwargs)
  File "/usr/local/lib/python3.9/site-packages/netmiko/base_connection.py", line 1473, in send_command
    command_string = self.normalize_cmd(command_string)
  File "/usr/local/lib/python3.9/site-packages/netmiko/base_connection.py", line 1632, in normalize_cmd
    command = command.rstrip()
AttributeError: 'list' object has no attribute 'rstrip'

2021-03-15 11:56:39,017 -  nornir.core -     INFO -        run() - Running task 'load_variable' with args {} on 6 hosts
2021-03-15 11:56:58,001 -  nornir.core -     INFO -        run() - Running task 'netmiko_send_command' with args {'command_string': ['show ip int br', 'show ip ospf neighbor', 'show ip bgp summary']} on 6 hosts
2021-03-15 11:56:58,086 - nornir.core.task -    ERROR -      start() - Host 'R2': task 'netmiko_send_command' failed with traceback:
Traceback (most recent call last):
  File "/usr/local/lib/python3.9/site-packages/nornir/core/task.py", line 98, in start
    r = self.task(self, **self.params)
  File "/usr/local/lib/python3.9/site-packages/nornir_netmiko/tasks/netmiko_send_command.py", line 32, in netmiko_send_command
    result = net_connect.send_command(command_string, **kwargs)
  File "/usr/local/lib/python3.9/site-packages/netmiko/utilities.py", line 429, in wrapper_decorator
    return func(self, *args, **kwargs)
  File "/usr/local/lib/python3.9/site-packages/netmiko/base_connection.py", line 1473, in send_command
    command_string = self.normalize_cmd(command_string)
  File "/usr/local/lib/python3.9/site-packages/netmiko/base_connection.py", line 1632, in normalize_cmd
    command = command.rstrip()
AttributeError: 'list' object has no attribute 'rstrip'

2021-03-15 11:56:58,086 - nornir.core.task -    ERROR -      start() - Host 'RR-2': task 'netmiko_send_command' failed with traceback:
Traceback (most recent call last):
  File "/usr/local/lib/python3.9/site-packages/nornir/core/task.py", line 98, in start
    r = self.task(self, **self.params)
  File "/usr/local/lib/python3.9/site-packages/nornir_netmiko/tasks/netmiko_send_command.py", line 32, in netmiko_send_command
    result = net_connect.send_command(command_string, **kwargs)
  File "/usr/local/lib/python3.9/site-packages/netmiko/utilities.py", line 429, in wrapper_decorator
    return func(self, *args, **kwargs)
  File "/usr/local/lib/python3.9/site-packages/netmiko/base_connection.py", line 1473, in send_command
    command_string = self.normalize_cmd(command_string)
  File "/usr/local/lib/python3.9/site-packages/netmiko/base_connection.py", line 1632, in normalize_cmd
    command = command.rstrip()
AttributeError: 'list' object has no attribute 'rstrip'

2021-03-15 11:56:58,106 - nornir.core.task -    ERROR -      start() - Host 'RR-1': task 'netmiko_send_command' failed with traceback:
Traceback (most recent call last):
  File "/usr/local/lib/python3.9/site-packages/nornir/core/task.py", line 98, in start
    r = self.task(self, **self.params)
  File "/usr/local/lib/python3.9/site-packages/nornir_netmiko/tasks/netmiko_send_command.py", line 32, in netmiko_send_command
    result = net_connect.send_command(command_string, **kwargs)
  File "/usr/local/lib/python3.9/site-packages/netmiko/utilities.py", line 429, in wrapper_decorator
    return func(self, *args, **kwargs)
  File "/usr/local/lib/python3.9/site-packages/netmiko/base_connection.py", line 1473, in send_command
    command_string = self.normalize_cmd(command_string)
  File "/usr/local/lib/python3.9/site-packages/netmiko/base_connection.py", line 1632, in normalize_cmd
    command = command.rstrip()
AttributeError: 'list' object has no attribute 'rstrip'

2021-03-15 11:56:58,106 - nornir.core.task -    ERROR -      start() - Host 'R4': task 'netmiko_send_command' failed with traceback:
Traceback (most recent call last):
  File "/usr/local/lib/python3.9/site-packages/nornir/core/task.py", line 98, in start
    r = self.task(self, **self.params)
  File "/usr/local/lib/python3.9/site-packages/nornir_netmiko/tasks/netmiko_send_command.py", line 32, in netmiko_send_command
    result = net_connect.send_command(command_string, **kwargs)
  File "/usr/local/lib/python3.9/site-packages/netmiko/utilities.py", line 429, in wrapper_decorator
    return func(self, *args, **kwargs)
  File "/usr/local/lib/python3.9/site-packages/netmiko/base_connection.py", line 1473, in send_command
    command_string = self.normalize_cmd(command_string)
  File "/usr/local/lib/python3.9/site-packages/netmiko/base_connection.py", line 1632, in normalize_cmd
    command = command.rstrip()
AttributeError: 'list' object has no attribute 'rstrip'

2021-03-15 11:56:58,123 - nornir.core.task -    ERROR -      start() - Host 'R1': task 'netmiko_send_command' failed with traceback:
Traceback (most recent call last):
  File "/usr/local/lib/python3.9/site-packages/nornir/core/task.py", line 98, in start
    r = self.task(self, **self.params)
  File "/usr/local/lib/python3.9/site-packages/nornir_netmiko/tasks/netmiko_send_command.py", line 32, in netmiko_send_command
    result = net_connect.send_command(command_string, **kwargs)
  File "/usr/local/lib/python3.9/site-packages/netmiko/utilities.py", line 429, in wrapper_decorator
    return func(self, *args, **kwargs)
  File "/usr/local/lib/python3.9/site-packages/netmiko/base_connection.py", line 1473, in send_command
    command_string = self.normalize_cmd(command_string)
  File "/usr/local/lib/python3.9/site-packages/netmiko/base_connection.py", line 1632, in normalize_cmd
    command = command.rstrip()
AttributeError: 'list' object has no attribute 'rstrip'

2021-03-15 11:56:58,147 - nornir.core.task -    ERROR -      start() - Host 'R3': task 'netmiko_send_command' failed with traceback:
Traceback (most recent call last):
  File "/usr/local/lib/python3.9/site-packages/nornir/core/task.py", line 98, in start
    r = self.task(self, **self.params)
  File "/usr/local/lib/python3.9/site-packages/nornir_netmiko/tasks/netmiko_send_command.py", line 32, in netmiko_send_command
    result = net_connect.send_command(command_string, **kwargs)
  File "/usr/local/lib/python3.9/site-packages/netmiko/utilities.py", line 429, in wrapper_decorator
    return func(self, *args, **kwargs)
  File "/usr/local/lib/python3.9/site-packages/netmiko/base_connection.py", line 1473, in send_command
    command_string = self.normalize_cmd(command_string)
  File "/usr/local/lib/python3.9/site-packages/netmiko/base_connection.py", line 1632, in normalize_cmd
    command = command.rstrip()
AttributeError: 'list' object has no attribute 'rstrip'

2021-03-15 12:04:24,756 -  nornir.core -     INFO -        run() - Running task 'load_variable' with args {} on 6 hosts
2021-03-15 12:04:43,833 -  nornir.core -     INFO -        run() - Running task 'netmiko_send_command' with args {'command_string': 'show ip ospf neighbor'} on 6 hosts
2021-03-15 12:19:58,642 -  nornir.core -     INFO -        run() - Running task 'load_variable' with args {} on 6 hosts
2021-03-15 12:20:15,600 -  nornir.core -     INFO -        run() - Running task 'netmiko_send_command' with args {'command_string': ['show ip ospf neighbor', 'show ip bgp summary']} on 6 hosts
2021-03-15 12:20:15,704 - nornir.core.task -    ERROR -      start() - Host 'R4': task 'netmiko_send_command' failed with traceback:
Traceback (most recent call last):
  File "/usr/local/lib/python3.9/site-packages/nornir/core/task.py", line 98, in start
    r = self.task(self, **self.params)
  File "/usr/local/lib/python3.9/site-packages/nornir_netmiko/tasks/netmiko_send_command.py", line 32, in netmiko_send_command
    result = net_connect.send_command(command_string, **kwargs)
  File "/usr/local/lib/python3.9/site-packages/netmiko/utilities.py", line 429, in wrapper_decorator
    return func(self, *args, **kwargs)
  File "/usr/local/lib/python3.9/site-packages/netmiko/base_connection.py", line 1473, in send_command
    command_string = self.normalize_cmd(command_string)
  File "/usr/local/lib/python3.9/site-packages/netmiko/base_connection.py", line 1632, in normalize_cmd
    command = command.rstrip()
AttributeError: 'list' object has no attribute 'rstrip'

2021-03-15 12:20:15,704 - nornir.core.task -    ERROR -      start() - Host 'R2': task 'netmiko_send_command' failed with traceback:
Traceback (most recent call last):
  File "/usr/local/lib/python3.9/site-packages/nornir/core/task.py", line 98, in start
    r = self.task(self, **self.params)
  File "/usr/local/lib/python3.9/site-packages/nornir_netmiko/tasks/netmiko_send_command.py", line 32, in netmiko_send_command
    result = net_connect.send_command(command_string, **kwargs)
  File "/usr/local/lib/python3.9/site-packages/netmiko/utilities.py", line 429, in wrapper_decorator
    return func(self, *args, **kwargs)
  File "/usr/local/lib/python3.9/site-packages/netmiko/base_connection.py", line 1473, in send_command
    command_string = self.normalize_cmd(command_string)
  File "/usr/local/lib/python3.9/site-packages/netmiko/base_connection.py", line 1632, in normalize_cmd
    command = command.rstrip()
AttributeError: 'list' object has no attribute 'rstrip'

2021-03-15 12:20:15,706 - nornir.core.task -    ERROR -      start() - Host 'RR-2': task 'netmiko_send_command' failed with traceback:
Traceback (most recent call last):
  File "/usr/local/lib/python3.9/site-packages/nornir/core/task.py", line 98, in start
    r = self.task(self, **self.params)
  File "/usr/local/lib/python3.9/site-packages/nornir_netmiko/tasks/netmiko_send_command.py", line 32, in netmiko_send_command
    result = net_connect.send_command(command_string, **kwargs)
  File "/usr/local/lib/python3.9/site-packages/netmiko/utilities.py", line 429, in wrapper_decorator
    return func(self, *args, **kwargs)
  File "/usr/local/lib/python3.9/site-packages/netmiko/base_connection.py", line 1473, in send_command
    command_string = self.normalize_cmd(command_string)
  File "/usr/local/lib/python3.9/site-packages/netmiko/base_connection.py", line 1632, in normalize_cmd
    command = command.rstrip()
AttributeError: 'list' object has no attribute 'rstrip'

2021-03-15 12:20:15,706 - nornir.core.task -    ERROR -      start() - Host 'RR-1': task 'netmiko_send_command' failed with traceback:
Traceback (most recent call last):
  File "/usr/local/lib/python3.9/site-packages/nornir/core/task.py", line 98, in start
    r = self.task(self, **self.params)
  File "/usr/local/lib/python3.9/site-packages/nornir_netmiko/tasks/netmiko_send_command.py", line 32, in netmiko_send_command
    result = net_connect.send_command(command_string, **kwargs)
  File "/usr/local/lib/python3.9/site-packages/netmiko/utilities.py", line 429, in wrapper_decorator
    return func(self, *args, **kwargs)
  File "/usr/local/lib/python3.9/site-packages/netmiko/base_connection.py", line 1473, in send_command
    command_string = self.normalize_cmd(command_string)
  File "/usr/local/lib/python3.9/site-packages/netmiko/base_connection.py", line 1632, in normalize_cmd
    command = command.rstrip()
AttributeError: 'list' object has no attribute 'rstrip'

2021-03-15 12:20:15,706 - nornir.core.task -    ERROR -      start() - Host 'R1': task 'netmiko_send_command' failed with traceback:
Traceback (most recent call last):
  File "/usr/local/lib/python3.9/site-packages/nornir/core/task.py", line 98, in start
    r = self.task(self, **self.params)
  File "/usr/local/lib/python3.9/site-packages/nornir_netmiko/tasks/netmiko_send_command.py", line 32, in netmiko_send_command
    result = net_connect.send_command(command_string, **kwargs)
  File "/usr/local/lib/python3.9/site-packages/netmiko/utilities.py", line 429, in wrapper_decorator
    return func(self, *args, **kwargs)
  File "/usr/local/lib/python3.9/site-packages/netmiko/base_connection.py", line 1473, in send_command
    command_string = self.normalize_cmd(command_string)
  File "/usr/local/lib/python3.9/site-packages/netmiko/base_connection.py", line 1632, in normalize_cmd
    command = command.rstrip()
AttributeError: 'list' object has no attribute 'rstrip'

2021-03-15 12:20:15,726 - nornir.core.task -    ERROR -      start() - Host 'R3': task 'netmiko_send_command' failed with traceback:
Traceback (most recent call last):
  File "/usr/local/lib/python3.9/site-packages/nornir/core/task.py", line 98, in start
    r = self.task(self, **self.params)
  File "/usr/local/lib/python3.9/site-packages/nornir_netmiko/tasks/netmiko_send_command.py", line 32, in netmiko_send_command
    result = net_connect.send_command(command_string, **kwargs)
  File "/usr/local/lib/python3.9/site-packages/netmiko/utilities.py", line 429, in wrapper_decorator
    return func(self, *args, **kwargs)
  File "/usr/local/lib/python3.9/site-packages/netmiko/base_connection.py", line 1473, in send_command
    command_string = self.normalize_cmd(command_string)
  File "/usr/local/lib/python3.9/site-packages/netmiko/base_connection.py", line 1632, in normalize_cmd
    command = command.rstrip()
AttributeError: 'list' object has no attribute 'rstrip'

2021-03-15 12:35:24,389 -  nornir.core -     INFO -        run() - Running task 'load_variable' with args {} on 6 hosts
2021-03-15 12:35:44,429 -  nornir.core -     INFO -        run() - Running task 'netmiko_send_command' with args {'command_string': ['show ip ospf neighbor', 'show ip bgp summary']} on 6 hosts
2021-03-15 12:35:44,513 - nornir.core.task -    ERROR -      start() - Host 'RR-1': task 'netmiko_send_command' failed with traceback:
Traceback (most recent call last):
  File "/usr/local/lib/python3.9/site-packages/nornir/core/task.py", line 98, in start
    r = self.task(self, **self.params)
  File "/usr/local/lib/python3.9/site-packages/nornir_netmiko/tasks/netmiko_send_command.py", line 32, in netmiko_send_command
    result = net_connect.send_command(command_string, **kwargs)
  File "/usr/local/lib/python3.9/site-packages/netmiko/utilities.py", line 429, in wrapper_decorator
    return func(self, *args, **kwargs)
  File "/usr/local/lib/python3.9/site-packages/netmiko/base_connection.py", line 1473, in send_command
    command_string = self.normalize_cmd(command_string)
  File "/usr/local/lib/python3.9/site-packages/netmiko/base_connection.py", line 1632, in normalize_cmd
    command = command.rstrip()
AttributeError: 'list' object has no attribute 'rstrip'

2021-03-15 12:35:44,513 - nornir.core.task -    ERROR -      start() - Host 'RR-2': task 'netmiko_send_command' failed with traceback:
Traceback (most recent call last):
  File "/usr/local/lib/python3.9/site-packages/nornir/core/task.py", line 98, in start
    r = self.task(self, **self.params)
  File "/usr/local/lib/python3.9/site-packages/nornir_netmiko/tasks/netmiko_send_command.py", line 32, in netmiko_send_command
    result = net_connect.send_command(command_string, **kwargs)
  File "/usr/local/lib/python3.9/site-packages/netmiko/utilities.py", line 429, in wrapper_decorator
    return func(self, *args, **kwargs)
  File "/usr/local/lib/python3.9/site-packages/netmiko/base_connection.py", line 1473, in send_command
    command_string = self.normalize_cmd(command_string)
  File "/usr/local/lib/python3.9/site-packages/netmiko/base_connection.py", line 1632, in normalize_cmd
    command = command.rstrip()
AttributeError: 'list' object has no attribute 'rstrip'

2021-03-15 12:35:44,552 - nornir.core.task -    ERROR -      start() - Host 'R2': task 'netmiko_send_command' failed with traceback:
Traceback (most recent call last):
  File "/usr/local/lib/python3.9/site-packages/nornir/core/task.py", line 98, in start
    r = self.task(self, **self.params)
  File "/usr/local/lib/python3.9/site-packages/nornir_netmiko/tasks/netmiko_send_command.py", line 32, in netmiko_send_command
    result = net_connect.send_command(command_string, **kwargs)
  File "/usr/local/lib/python3.9/site-packages/netmiko/utilities.py", line 429, in wrapper_decorator
    return func(self, *args, **kwargs)
  File "/usr/local/lib/python3.9/site-packages/netmiko/base_connection.py", line 1473, in send_command
    command_string = self.normalize_cmd(command_string)
  File "/usr/local/lib/python3.9/site-packages/netmiko/base_connection.py", line 1632, in normalize_cmd
    command = command.rstrip()
AttributeError: 'list' object has no attribute 'rstrip'

2021-03-15 12:35:44,575 - nornir.core.task -    ERROR -      start() - Host 'R4': task 'netmiko_send_command' failed with traceback:
Traceback (most recent call last):
  File "/usr/local/lib/python3.9/site-packages/nornir/core/task.py", line 98, in start
    r = self.task(self, **self.params)
  File "/usr/local/lib/python3.9/site-packages/nornir_netmiko/tasks/netmiko_send_command.py", line 32, in netmiko_send_command
    result = net_connect.send_command(command_string, **kwargs)
  File "/usr/local/lib/python3.9/site-packages/netmiko/utilities.py", line 429, in wrapper_decorator
    return func(self, *args, **kwargs)
  File "/usr/local/lib/python3.9/site-packages/netmiko/base_connection.py", line 1473, in send_command
    command_string = self.normalize_cmd(command_string)
  File "/usr/local/lib/python3.9/site-packages/netmiko/base_connection.py", line 1632, in normalize_cmd
    command = command.rstrip()
AttributeError: 'list' object has no attribute 'rstrip'

2021-03-15 12:35:44,581 - nornir.core.task -    ERROR -      start() - Host 'R3': task 'netmiko_send_command' failed with traceback:
Traceback (most recent call last):
  File "/usr/local/lib/python3.9/site-packages/nornir/core/task.py", line 98, in start
    r = self.task(self, **self.params)
  File "/usr/local/lib/python3.9/site-packages/nornir_netmiko/tasks/netmiko_send_command.py", line 32, in netmiko_send_command
    result = net_connect.send_command(command_string, **kwargs)
  File "/usr/local/lib/python3.9/site-packages/netmiko/utilities.py", line 429, in wrapper_decorator
    return func(self, *args, **kwargs)
  File "/usr/local/lib/python3.9/site-packages/netmiko/base_connection.py", line 1473, in send_command
    command_string = self.normalize_cmd(command_string)
  File "/usr/local/lib/python3.9/site-packages/netmiko/base_connection.py", line 1632, in normalize_cmd
    command = command.rstrip()
AttributeError: 'list' object has no attribute 'rstrip'

2021-03-15 12:35:44,581 - nornir.core.task -    ERROR -      start() - Host 'R1': task 'netmiko_send_command' failed with traceback:
Traceback (most recent call last):
  File "/usr/local/lib/python3.9/site-packages/nornir/core/task.py", line 98, in start
    r = self.task(self, **self.params)
  File "/usr/local/lib/python3.9/site-packages/nornir_netmiko/tasks/netmiko_send_command.py", line 32, in netmiko_send_command
    result = net_connect.send_command(command_string, **kwargs)
  File "/usr/local/lib/python3.9/site-packages/netmiko/utilities.py", line 429, in wrapper_decorator
    return func(self, *args, **kwargs)
  File "/usr/local/lib/python3.9/site-packages/netmiko/base_connection.py", line 1473, in send_command
    command_string = self.normalize_cmd(command_string)
  File "/usr/local/lib/python3.9/site-packages/netmiko/base_connection.py", line 1632, in normalize_cmd
    command = command.rstrip()
AttributeError: 'list' object has no attribute 'rstrip'

2021-03-15 12:36:34,583 -  nornir.core -     INFO -        run() - Running task 'load_variable' with args {} on 6 hosts
2021-03-15 12:36:53,667 -  nornir.core -     INFO -        run() - Running task 'netmiko_send_command' with args {'commands': ['show ip ospf neighbor', 'show ip bgp summary']} on 6 hosts
2021-03-15 12:36:53,669 - nornir.core.task -    ERROR -      start() - Host 'RR-2': task 'netmiko_send_command' failed with traceback:
Traceback (most recent call last):
  File "/usr/local/lib/python3.9/site-packages/nornir/core/task.py", line 98, in start
    r = self.task(self, **self.params)
TypeError: netmiko_send_command() missing 1 required positional argument: 'command_string'

2021-03-15 12:36:53,669 - nornir.core.task -    ERROR -      start() - Host 'RR-1': task 'netmiko_send_command' failed with traceback:
Traceback (most recent call last):
  File "/usr/local/lib/python3.9/site-packages/nornir/core/task.py", line 98, in start
    r = self.task(self, **self.params)
TypeError: netmiko_send_command() missing 1 required positional argument: 'command_string'

2021-03-15 12:36:53,669 - nornir.core.task -    ERROR -      start() - Host 'R1': task 'netmiko_send_command' failed with traceback:
Traceback (most recent call last):
  File "/usr/local/lib/python3.9/site-packages/nornir/core/task.py", line 98, in start
    r = self.task(self, **self.params)
TypeError: netmiko_send_command() missing 1 required positional argument: 'command_string'

2021-03-15 12:36:53,670 - nornir.core.task -    ERROR -      start() - Host 'R2': task 'netmiko_send_command' failed with traceback:
Traceback (most recent call last):
  File "/usr/local/lib/python3.9/site-packages/nornir/core/task.py", line 98, in start
    r = self.task(self, **self.params)
TypeError: netmiko_send_command() missing 1 required positional argument: 'command_string'

2021-03-15 12:36:53,670 - nornir.core.task -    ERROR -      start() - Host 'R3': task 'netmiko_send_command' failed with traceback:
Traceback (most recent call last):
  File "/usr/local/lib/python3.9/site-packages/nornir/core/task.py", line 98, in start
    r = self.task(self, **self.params)
TypeError: netmiko_send_command() missing 1 required positional argument: 'command_string'

2021-03-15 12:36:53,670 - nornir.core.task -    ERROR -      start() - Host 'R4': task 'netmiko_send_command' failed with traceback:
Traceback (most recent call last):
  File "/usr/local/lib/python3.9/site-packages/nornir/core/task.py", line 98, in start
    r = self.task(self, **self.params)
TypeError: netmiko_send_command() missing 1 required positional argument: 'command_string'

2021-03-15 12:42:47,979 -  nornir.core -     INFO -        run() - Running task 'load_variable' with args {} on 6 hosts
2021-03-15 12:43:08,961 -  nornir.core -     INFO -        run() - Running task 'send_commands' with args {'commands': ['show ip ospf neighbor', 'show ip bgp summary']} on 6 hosts
2021-03-15 13:01:54,764 -  nornir.core -     INFO -        run() - Running task 'load_variable' with args {} on 6 hosts
2021-03-15 13:02:14,337 -  nornir.core -     INFO -        run() - Running task 'send_commands' with args {'commands': ['show ip ospf neighbor', 'show ip bgp summary']} on 6 hosts
2021-03-15 13:05:29,481 -  nornir.core -     INFO -        run() - Running task 'load_variable' with args {} on 6 hosts
2021-03-15 13:05:50,560 -  nornir.core -     INFO -        run() - Running task 'send_commands' with args {'commands': ['show ip ospf neighbor', 'show ip bgp summary']} on 6 hosts
2021-03-15 13:10:28,813 -  nornir.core -     INFO -        run() - Running task 'load_variable' with args {} on 6 hosts
2021-03-15 13:10:46,942 -  nornir.core -     INFO -        run() - Running task 'send_commands' with args {'commands': ['show ip ospf neighbor', 'show ip bgp summary']} on 6 hosts
2021-03-15 13:23:50,360 -  nornir.core -     INFO -        run() - Running task 'load_variable' with args {} on 6 hosts
2021-03-15 13:24:07,957 -  nornir.core -     INFO -        run() - Running task 'send_commands' with args {'commands': ['show ip ospf neighbor', 'show ip bgp summary']} on 6 hosts
2021-03-15 13:28:45,529 -  nornir.core -     INFO -        run() - Running task 'load_variable' with args {} on 6 hosts
2021-03-15 13:29:07,705 -  nornir.core -     INFO -        run() - Running task 'show_status_ospf_bgp' with args {} on 6 hosts
2021-03-15 13:32:22,345 -  nornir.core -     INFO -        run() - Running task 'load_variable' with args {} on 6 hosts
2021-03-15 13:32:42,125 -  nornir.core -     INFO -        run() - Running task 'show_status_ospf_bgp' with args {} on 6 hosts
2021-03-15 13:35:35,222 -  nornir.core -     INFO -        run() - Running task 'load_variable' with args {} on 6 hosts
2021-03-15 13:35:56,561 -  nornir.core -     INFO -        run() - Running task 'show_status_ospf_bgp' with args {} on 6 hosts
2021-03-15 13:37:10,544 -  nornir.core -     INFO -        run() - Running task 'load_variable' with args {} on 6 hosts
2021-03-15 13:37:27,701 -  nornir.core -     INFO -        run() - Running task 'show_status_ospf_bgp' with args {} on 6 hosts
2021-03-15 14:14:29,791 -  nornir.core -     INFO -        run() - Running task 'load_variable' with args {} on 6 hosts
2021-03-15 14:14:50,534 -  nornir.core -     INFO -        run() - Running task 'show_status_ospf_bgp' with args {} on 6 hosts
